Workbook
Name _1DP2_: [1]FB25JN!$L$3:$M$3
Name ☞_기능점수__산정방법_선택: '[2]01.수집모듈(FP)'!#REF!
Name A: #REF!
Name A: #REF!
Name ACC: [3]FB25JN!$L$3:$M$3
Name ACCESS: [3]FB25JN!$L$3:$M$3
Name ACCESS2: [3]FB25JN!$L$6:$M$6
Name adfdf: [4]수량집계!#REF!
Name adfdf: [4]수량집계!#REF!
Name afc: [5]수량산출1!$A$528:$AB$626
Name AFC설비: #REF!
Name AFC설비: #REF!
Name b: #REF!
Name b: #REF!
Name BASIC: [6]BASIC!$A$1:$D$340
Name CCTV설비: #REF!
Name CCTV설비: #REF!
Name CODE: [7]공종코드!$A$5:$E$359
Name CODEA: #REF!
Name CODEA: #REF!
Name CODEB: #REF!
Name CODEB: #REF!
Name cost: [8]cost!$A$2:$V$224
Name Dp: #REF!
Name Dp: #REF!
Name HANIWALL_FB: #REF!
Name HANIWALL_FB: #REF!
Name HANIWALL_GC: #REF!
Name HANIWALL_GC: #REF!
Name MDL: [9]sheet1!$A$1:$A$65536
Name MODEL: #REF!
Name MODEL: #REF!
Name PL50T: #REF!
Name PL50T: #REF!
Name RANGE: #REF!
Name RANGE: #REF!
Name rhd: [4]수량집계!#REF!
Name rhd: [4]수량집계!#REF!
Name RNG: [9]sheet1!$A$1:$D$65536
Name SERVER: #REF!
Name SERVER: #REF!
Name SM: #REF!
Name SM: #REF!
Name sngc50t: [10]FB25JN!$L$6:$M$6
Name SVR: #REF!
Name SVR: #REF!
Name SVRAG: #REF!
Name SVRAG: #REF!
Name SVRDESC: #REF!
Name SVRDESC: #REF!
Name TABLE: [4]수량집계!#REF!
Name TABLE: [4]수량집계!#REF!
Name TABLE_14: [4]수량집계!#REF!
Name TABLE_14: [4]수량집계!#REF!
Name TABLE_15: [4]수량집계!#REF!
Name TABLE_15: [4]수량집계!#REF!
Name TABLE_2: [4]수량집계!#REF!
Name TABLE_2: [4]수량집계!#REF!
Name TABLE_23: [4]수량집계!#REF!
Name TABLE_23: [4]수량집계!#REF!

Sheet SW세부산출내역
B2: 세부산출내역서
B6: 기준일 : | C6: 2025년 12월 일
B10: 건 명 : | C10: 2025년 제주스마트도시 데이터허브 시범솔루션 발굴사업
B11: 금 액 : | C11: ="일금"&NUMBERSTRING(H32,1)&"원정(VAT포함)" -> 일금일십구억원정(VAT포함) | E11: =H32 -> 1900000000
B13: 번호 | C13: 항 목 | D13: 규 격 | E13: 단위 | F13: 수량 | G13: 단가 | H13: 금액(원) | J13: 비 고
B14: 1 | C14: S/W | D14: 실증관련 데이터허브 고도화 | E14: 식 | F14: 1 | G14: =(상세내역!J12)+(상세내역!J15) -> 625600000 | H14: =G14 -> 625600000
B15: 2 | C15: S/W | D15: 공영주차장 스마트 안전 AI 분석 솔루션 | E15: 식 | F15: 1 | G15: =(상세내역!J16)+(상세내역!J17)+(상세내역!J18)+(상세내역!J19) -> 1274400000 | H15: =G15 -> 1274400000
B29: 계 | H29: =SUM(H14:I28) -> 1900000000
B30: 부가가치세(10%)
B31: 합 계 | H31: =SUM(H29:I30) -> 1900000000
B32: 견적가 | H32: =ROUNDDOWN(H31*1,-6) -> 1900000000
B34: 1. 개발기간 : 계약후 8개월
J40: 끝.

Sheet 상세내역
B1: 2025년 제주 스마트도시 데이터허브 시범솔루션 발굴사업
B3: =TEXT("견적금액 : 일금 ",1)&TEXT(NUMBERSTRING(H9,1),1)&TEXT("원정 ",1)&"("&DOLLAR(H9)&TEXT("_VAT포함)",1) -> #REF!
B4: 번호 | C4: 목록 | E4: 내역 | H4: 수량 | I4: 금액 | J4: 비고
B5: 1 | C5: H/W | D5: 스마트시티 데이터허브 플랫폼 장비 | H5: 1 | I5: =#REF! -> #REF!
B6: 2 | C6: S/W | D6: 스마트시티 데이터허브 플랫폼 S/W | H6: 1 | I6: =J21 -> 1149600000
B7: 공 급 가 | H7: =SUM(I5:I6) -> #REF!
B8: 부 가 세 | H8: =H7*10% -> #REF!
B9: 총 계 | H9: =SUM(H7:I8) -> #REF!
B10: 1. 2025년 제주스마트도시 데이터허브 시범솔루션 발굴사업 | J10: (단위: 원, 부가가치세포함)
B11: 구분 | C11: 항목 | E11: 내역 | H11: 수량 | I11: 단가 | J11: 합계
C12: 실증관련 데이터허브 고도화 | D12: 01.데이터 수집·통합·표준화 | E12: OCR 처리 - 민원 첨부 이미지·스캔 PDF를 인식하여 텍스트로 변환하고 NGSI-LD 표준 형식으로 구조화 | H12: 1 | I12: =('01. 데이터 수집·통합·표준화 개발 용역'!J12) -> 254300000 | J12: =H12*I12 -> 254300000
E13: RPA 수집 - 행정포털·민원포털·콜센터 등에서 비정형 데이터를 자동 수집·적재하는 프로세스 구축
E14: STT 처리 - 콜센터 음성 민원을 실시간 텍스트로 전환하고 개인정보를 자동 비식별화하여 저장
D15: 02.데이터전처리 | E15: 데이터 전처리 - 데이터 수집 : 행정·민원, 통합관제센터, 외부 공공데이터 수집 - 데이터 연계 : NGSI-LD 기반 데이터 호환성 확보 및 연계 처리 - 데이터 저장 : 데이터 적재·카탈로그화 및 API 기반 검색·공유 | H15: 1 | I15: =('02.데이터 전처리 용역'!J12) -> 371300000 | J15: =H15*I15 -> 371300000
C16: 공영주차장 스마트 안전 AI 분석 솔루션 | D16: 03.데이터 분석 | E16: 이벤트 데이터 분석 기능 - 다중 센서 기반 이벤트 데이터를 NGSI-LD 표준으로 변환·정규화하여 저장·분석하는 기능 LLM 기반 자연어 처리 응용 기능 | H16: 1 | I16: =('03.데이터 분석 기능 개발 용역'!J12) -> 124800000 | J16: =H16*I16 -> 124800000
D17: 04.AI 기술 | E17: LLM 기반 자연어 처리 응용 기능 - 민원·행정 데이터를 요약·분류·클러스터링하고 정책 보고서·민원 답변문을 자동 생성하는 LLM 기반 자연어 처리 기능 | H17: 1 | I17: =('04. LLM 기반 자연어 처리 응용 기능 용역'!J12) -> 608700000 | J17: =H17*I17 -> 608700000
D18: 05.AI 기술 | E18: AI Assistant 기능 - 대화형 질의응답, 다국어 응답, 정책 문서 검색·근거 제시 등 행정업무 지원을 위한 AI Assistant 기능 | H18: 1 | I18: =('05.AI Assistant 기능 개발 용역'!J12) -> 142600000 | J18: =H18*I18 -> 142600000
D19: 06.대시보드 | E19: 대시보드 및 시각화 - 데이터 수집·분석 결과, 이벤트 감시 현황, 성능·품질 지표를 시각적으로 제공하는 통합 대시보드 기능 | H19: 1 | I19: =('06.대시보드 및 시각화 개발 용역'!J12) -> 398300000 | J19: =H19*I19 -> 398300000
C20: 표준화 | D20: 07.데이터표준화 | E20: 데이터 표준화 모델 마련 - 도시 데이터 수집 시 데이터 연계 표준(NGSI-LD)를 준수하고, TTA의 데이터모델 표준(TTAK.KO-10.1331-Part4/R1) 반영 | H20: 1 | I20: =('07. 데이터 표준화 모델'!F19) -> 1.0032854e+08 | J20: =H20*I20 -> 1.0032854e+08
C21: 합계 | J21: =SUM(J17:J19) -> 1149600000

Sheet 01. 데이터 수집·통합·표준화 개발 용역
A1: 데이터 수집·통합·표준화 기능 개발 용역
K2: (소프트웨어사업 대가산정 가이드, 24.05.13. (FP방식-간이법), KOSA)
A4: ○ 개발원가 산정 | J4: (단위 : 원)
A5: 총기능점수 | C5: 기능점수당 단가 | E5: 보정계수 | J5: 개발원가 | K5: 비고
E6: 규모 | F6: 연계복잡성 | G6: 성능 | H6: 다중사이트 | I6: 보안성
A7: =I31 -> 268.3 | C7: 605784 | E7: =J22 -> 1.28 | F7: =J23 -> 0.94 | G7: =J24 -> 1 | H7: =J25 -> 1 | I7: =J26 -> 1 | J7: =PRODUCT(A7:I7) -> 1.9555832e+08
A8: 합계(보정 후 개발원가) | J8: =SUM(J7:K7) -> 1.9555832e+08
A9: 기업이윤 | I9: 0.192 | J9: =J8*I9 -> 37547197
A10: 직접경비 | J10: -1883000
A11: 소프트웨어 개발비(부가세 별도) | J11: =J8+J9+J10 -> 2.3122252e+08
A12: 소프트웨어 개발비(부가세 포함, 10만원 이하 절사) | J12: =ROUNDDOWN(J11*1.1, -5) -> 254300000
A14: ○ 직접경비 | J14: (단위 : 원)
A15: 구분 | C15: 산출내역 | J15: 금액
A18: 합 계 | J18: =SUM(J16:K17) -> 0
A20: ○ 보정계수 산정
A21: 보정계수 구분 | C21: 복잡도 및 난이도 수준 | J21: 보정계수
A22: SW규모 | C22: ="= 0.4057 x (log e("&A7&") - 7.1978)^2 + 0.8878 (단, 500FP 미만 1.28, 3,000FP 초과 1.153 적용)" -> = 0.4057 x (log e(268.3) - 7.1978)^2 + 0.8878 (단, 500FP 미만 1.28, 3,000FP 초과 1.153 적용) | J22: =IF(A7<500,1.28,IF(A7>3000,1.153,0.4057*(LN(A7)-7.1978)^2+0.8878)) -> 1.28
A23: 연계복잡성 | C23: 2. 1~2개의 타 기관 연계 | J23: =VLOOKUP(C23,M23:N27,2,1) -> 0.94 | M23: 1. 타 기관 연계 없음 | N23: 0.88
A24: 성능 요구수준 | C24: 3. 응답시간이나 처리율이 피크타임(peak time)에 중요하며, 처리 시한이 명시되어 있다. | J24: =VLOOKUP(C24,M28:N32,2,1) -> 1 | M24: 2. 1~2개의 타 기관 연계 | N24: 0.94
A25: 다중사이트 운영성 | C25: 2. 다중사이트 운영성에 대한 요구사항이 있으며, 동일 하드웨어 및 소프트웨어 환경에서 운영되도록 설계된다. | J25: =VLOOKUP(C25,M33:N37,2,1) -> 1 | M25: 3. 3~5개의 타 기관 연계 | N25: 1
A26: 보안성 요구수준 | C26: 2. 위의 4가지 항목 중 2가지 요구사항이 포함되어 있다. | J26: =VLOOKUP(C26,M38:N42,2,1) -> 1 | M26: 4. 6~10개의 타 기관 연계 | N26: 1.06
M27: 5. 10개 초과의 타 기관 연계 | N27: 1.12
A28: ○ FP 집계 | M28: 1. 응답성능에 대한 특별한 요구사항이 없다. | N28: 0.91
A29: 구분 | D29: ILF | E29: EIF | F29: EI | G29: EO | H29: EQ | I29: 계 | M29: 2. 응답성능에 대한 요구사항이 있으나 특별한 조치가 필요하지는 않다. | N29: 0.95
A30: 기능수 | D30: =COUNTIF('01. 데이터 수집·통합·표준화 FP산정'!E4:E73,"ILF") -> 15 | E30: =COUNTIF('01. 데이터 수집·통합·표준화 FP산정'!E4:E73,"EIF") -> 7 | F30: =COUNTIF('01. 데이터 수집·통합·표준화 FP산정'!E4:E73,"EI") -> 10 | G30: =COUNTIF('01. 데이터 수집·통합·표준화 FP산정'!E4:E73,"EO") -> 6 | H30: =COUNTIF('01. 데이터 수집·통합·표준화 FP산정'!E4:E73,"EQ") -> 12 | I30: =SUM(D30:H30) -> 50 | M30: 3. 응답시간이나 처리율이 피크타임(peak time)에 중요하며, 처리 시한이 명시되어 있다. | N30: 1
A31: 기능점수 | D31: =SUMIF('01. 데이터 수집·통합·표준화 FP산정'!E4:E79,"ILF",'01. 데이터 수집·통합·표준화 FP산정'!$F4:$F79) -> 112.5 | E31: =SUMIF('01. 데이터 수집·통합·표준화 FP산정'!E4:E79,"EIF",'01. 데이터 수집·통합·표준화 FP산정'!$F4:$F79) -> 37.8 | F31: =SUMIF('01. 데이터 수집·통합·표준화 FP산정'!E4:E79,"EI",'01. 데이터 수집·통합·표준화 FP산정'!$F4:$F79) -> 40 | G31: =SUMIF('01. 데이터 수집·통합·표준화 FP산정'!E4:E79,"EO",'01. 데이터 수집·통합·표준화 FP산정'!$F4:$F79) -> 31.2 | H31: =SUMIF('01. 데이터 수집·통합·표준화 FP산정'!E4:E79,"EQ",'01. 데이터 수집·통합·표준화 FP산정'!$F4:$F79) -> 46.8 | I31: =SUM(D31:H31) -> 268.3 | M31: 4. 응답시간이나 처리율이 모든 업무시간에 중요하며, 처리 시한이 명시되어 있다. | N31: 1.05
A32: 비중 | D32: =IF($I$31>0,D31/$I$31,"-") -> 0.41930675 | E32: =IF($I$31>0,E31/$I$31,"-") -> 0.14088707 | F32: =IF($I$31>0,F31/$I$31,"-") -> 0.14908684 | G32: =IF($I$31>0,G31/$I$31,"-") -> 0.11628774 | H32: =IF($I$31>0,H31/$I$31,"-") -> 0.17443161 | I32: =SUM(D32:H32) -> 1 | M32: 5. 응답성능 요구수준이 엄격하여, 설계, 개발 또는 구현 단계에서 성능 분석도구 사용이 필요하다. | N32: 1.09
M33: 1. 다중사이트 운영성에 대한 요구사항이 없다. | N33: 0.94
M34: 2. 다중사이트 운영성에 대한 요구사항이 있으며, 동일 하드웨어 및 소프트웨어 환경에서 운영되도록 설계된다. | N34: 1
M35: 3. 다중사이트 운영성에 대한 요구사항이 있으며, 유사 하드웨어 및 소프트웨어 환경에서 운영되도록 설계된다. | N35: 1.06
M36: 4. 다중사이트 운영성에 대한 요구사항이 있으며, 이질적인 하드웨어 및 소프트웨어 환경에서 운영되도록 설계된다. | N36: 1.13
M37: 5. 항목 4에 더하여 일반적 산출물 이외에 다중사이트에서 원활한 운영을 보장하기 위한 운영 절차의 문서화와 사전 모의훈련이 요구된다. | N37: 1.19
M38: 1. 암호화, 웹취약점 점검, 시큐어코딩, 개인정보보호 중 1가지 요구사항이 포함되어 있다. | N38: 0.97
M39: 2. 위의 4가지 항목 중 2가지 요구사항이 포함되어 있다. | N39: 1
M40: 3. 위의 4가지 항목 중 3가지 요구사항이 포함되어 있다. | N40: 1.03
M41: 4. 위의 4가지 항목이 모두 포함되어 있다. | N41: 1.06
M42: 5. 항목 4)에 더하여 추가적인 요구사항이 있다. | N42: 1.08
A44: FP산정
A45: FP산정

Sheet 01. 데이터 수집·통합·표준화 FP산정
A1: 데이터 수집·통합·표준화 기능점수
A2: 기능명 | E2: 데이터 및 트랜잭션 기능 | F2: FP 산출 | G2: 비고
A3: ①어플리 케이션명 | B3: ②세부 업무명 | C3: ③단위프로세스명 | D3: 단위프로세스 설명 | E3: ④FP유형 | F3: ⑤가중치
A4: 실증관련 데이터허브 고도화 | B4: 민원 데이터 수집 | C4: NGSI-LD 민원 데이터 모델 정의 | D4: 민원 데이터의 엔티티/속성 표준모델 정의 | E4: ILF | F4: =IF(E4="","",IF(E4="EI",4,IF(E4="EO",5.2,IF(E4="EQ",3.9,IF(E4="ILF",7.5,IF(E4="EIF",5.4)))))) -> 7.5
C5: RPA/ETL 수집 플로우 개발 | D5: 포털·만덕콜센터 데이터 자동수집, OCR/STT 포함 | E5: EI | F5: =IF(E5="","",IF(E5="EI",4,IF(E5="EO",5.2,IF(E5="EQ",3.9,IF(E5="ILF",7.5,IF(E5="EIF",5.4)))))) -> 4
C6: 수집 어댑터 설정 및 등록 | D6: 포털 API·파일서버 연계 어댑터 설정 | E6: EI | F6: =IF(E6="","",IF(E6="EI",4,IF(E6="EO",5.2,IF(E6="EQ",3.9,IF(E6="ILF",7.5,IF(E6="EIF",5.4)))))) -> 4
C7: 수집 결과 조회 및 검증 | D7: 수집 성공/실패 로그, 정상 여부 확인 | E7: EQ | F7: =IF(E7="","",IF(E7="EI",4,IF(E7="EO",5.2,IF(E7="EQ",3.9,IF(E7="ILF",7.5,IF(E7="EIF",5.4)))))) -> 3.9
B8: 센싱 이벤트 수집 | C8: NGSI-LD 이벤트 데이터 모델 정의 | D8: 화재·온도·음향 이벤트 엔티티 정의 | E8: ILF | F8: =IF(E8="","",IF(E8="EI",4,IF(E8="EO",5.2,IF(E8="EQ",3.9,IF(E8="ILF",7.5,IF(E8="EIF",5.4)))))) -> 7.5
C9: 실시간 이벤트 수집 플로우 개발 | D9: Kafka/ETL 기반 센서 이벤트 정규화 | E9: EI | F9: =IF(E9="","",IF(E9="EI",4,IF(E9="EO",5.2,IF(E9="EQ",3.9,IF(E9="ILF",7.5,IF(E9="EIF",5.4)))))) -> 4
C10: 센싱 서버 어댑터 설정 및 등록 | D10: CCTV·음원·열화상 서버 연계 | E10: EI | F10: =IF(E10="","",IF(E10="EI",4,IF(E10="EO",5.2,IF(E10="EQ",3.9,IF(E10="ILF",7.5,IF(E10="EIF",5.4)))))) -> 4
C11: 결과 검증 및 동기화 | D11: 시간/공간 동기화 및 다중센서 매칭 | E11: EQ | F11: =IF(E11="","",IF(E11="EI",4,IF(E11="EO",5.2,IF(E11="EQ",3.9,IF(E11="ILF",7.5,IF(E11="EIF",5.4)))))) -> 3.9
B12: 충전 인프라 데이터 수집 | C12: NGSI-LD 충전 데이터 모델 정의 | D12: 충전기·세션 엔티티 정의 | E12: ILF | F12: =IF(E12="","",IF(E12="EI",4,IF(E12="EO",5.2,IF(E12="EQ",3.9,IF(E12="ILF",7.5,IF(E12="EIF",5.4)))))) -> 7.5
C13: 충전 운영데이터 수집 플로우 개발 | D13: 상태/세션 로그·이상코드 스트리밍 | E13: EI | F13: =IF(E13="","",IF(E13="EI",4,IF(E13="EO",5.2,IF(E13="EQ",3.9,IF(E13="ILF",7.5,IF(E13="EIF",5.4)))))) -> 4
C14: 충전기 어댑터 설정 및 등록 | D14: 운영시스템 API 연계 | E14: EI | F14: =IF(E14="","",IF(E14="EI",4,IF(E14="EO",5.2,IF(E14="EQ",3.9,IF(E14="ILF",7.5,IF(E14="EIF",5.4)))))) -> 4
C15: 수집 결과 검증 및 이상탐지 | D15: 충전 실패·장기점유 패턴 검출 | E15: EQ | F15: =IF(E15="","",IF(E15="EI",4,IF(E15="EO",5.2,IF(E15="EQ",3.9,IF(E15="ILF",7.5,IF(E15="EIF",5.4)))))) -> 3.9
B16: 외부데이터 연계 | C16: NGSI-LD 외부데이터 모델 정의 | D16: 기상·112·119 데이터 엔티티 정의 | E16: ILF | F16: =IF(E16="","",IF(E16="EI",4,IF(E16="EO",5.2,IF(E16="EQ",3.9,IF(E16="ILF",7.5,IF(E16="EIF",5.4)))))) -> 7.5
C17: API 연계 플로우 개발 | D17: 기상청·112·119 긴급구조 API 호출 및 적재 | E17: EI | F17: =IF(E17="","",IF(E17="EI",4,IF(E17="EO",5.2,IF(E17="EQ",3.9,IF(E17="ILF",7.5,IF(E17="EIF",5.4)))))) -> 4
C18: API 어댑터 설정 및 등록 | D18: 외부 API 인증키·주기 관리 | E18: EIF | F18: =IF(E18="","",IF(E18="EI",4,IF(E18="EO",5.2,IF(E18="EQ",3.9,IF(E18="ILF",7.5,IF(E18="EIF",5.4)))))) -> 5.4
C19: 수집 결과 검증 | D19: API 응답 성공/실패 로그, 지연 모니터링 | E19: EQ | F19: =IF(E19="","",IF(E19="EI",4,IF(E19="EO",5.2,IF(E19="EQ",3.9,IF(E19="ILF",7.5,IF(E19="EIF",5.4)))))) -> 3.9
B20: 통합플랫폼 연계 | C20: NGSI-LD 통합플랫폼 모델 정의 | D20: 통합관제·허브 메타데이터 모델 정의 | E20: ILF | F20: =IF(E20="","",IF(E20="EI",4,IF(E20="EO",5.2,IF(E20="EQ",3.9,IF(E20="ILF",7.5,IF(E20="EIF",5.4)))))) -> 7.5
C21: 플랫폼 연계 플로우 개발 | D21: 통합관제·허브 데이터 연계 수집 | E21: EI | F21: =IF(E21="","",IF(E21="EI",4,IF(E21="EO",5.2,IF(E21="EQ",3.9,IF(E21="ILF",7.5,IF(E21="EIF",5.4)))))) -> 4
C22: 플랫폼 어댑터 설정 및 등록 | D22: 관제·허브 API/메시지큐 인터페이스 | E22: EIF | F22: =IF(E22="","",IF(E22="EI",4,IF(E22="EO",5.2,IF(E22="EQ",3.9,IF(E22="ILF",7.5,IF(E22="EIF",5.4)))))) -> 5.4
C23: 수집 결과 검증 | D23: 데이터 중복/지연 검증 | E23: EQ | F23: =IF(E23="","",IF(E23="EI",4,IF(E23="EO",5.2,IF(E23="EQ",3.9,IF(E23="ILF",7.5,IF(E23="EIF",5.4)))))) -> 3.9
B24: 데이터허브연계 | C24: 데이터허브 데이터 모델 입력 | D24: 데이터 허브 데이터 연계 모델 입력 기능 | E24: EIF | F24: =IF(E24="","",IF(E24="EI",4,IF(E24="EO",5.2,IF(E24="EQ",3.9,IF(E24="ILF",7.5,IF(E24="EIF",5.4)))))) -> 5.4
C25: 데이터허브 컨텍스트 정보 입력 | D25: 데이터 허브 컨텍스트 정보 입력 기능 | E25: EIF | F25: =IF(E25="","",IF(E25="EI",4,IF(E25="EO",5.2,IF(E25="EQ",3.9,IF(E25="ILF",7.5,IF(E25="EIF",5.4)))))) -> 5.4
C26: 데이터허브 데이터 셋 입력 | D26: 연계 대상 데이터 허브 데이터 셋 입력 기능 | E26: EIF | F26: =IF(E26="","",IF(E26="EI",4,IF(E26="EO",5.2,IF(E26="EQ",3.9,IF(E26="ILF",7.5,IF(E26="EIF",5.4)))))) -> 5.4
C27: 데이터허브 데이터 셋 플로우 입력 | D27: 연계 대상 데이터 허브 데이터 셋 플로우 입력 기능 | E27: EIF | F27: =IF(E27="","",IF(E27="EI",4,IF(E27="EO",5.2,IF(E27="EQ",3.9,IF(E27="ILF",7.5,IF(E27="EIF",5.4)))))) -> 5.4
C28: 데이터허브 구독 입력 | D28: 연계 대상 데이터 허브 구독 입력 기능 | E28: EIF | F28: =IF(E28="","",IF(E28="EI",4,IF(E28="EO",5.2,IF(E28="EQ",3.9,IF(E28="ILF",7.5,IF(E28="EIF",5.4)))))) -> 5.4
C29: 데이터허브 최종 데이터 조회 | D29: 연계 대상 데이터 허브 최종 데이터 조회 기능 | E29: EQ | F29: =IF(E29="","",IF(E29="EI",4,IF(E29="EO",5.2,IF(E29="EQ",3.9,IF(E29="ILF",7.5,IF(E29="EIF",5.4)))))) -> 3.9
C30: 데이터허브 이력 데이터 조회 | D30: 연계 대상 데이터 허브 이력 데이터 조회 기능 | E30: EQ | F30: =IF(E30="","",IF(E30="EI",4,IF(E30="EO",5.2,IF(E30="EQ",3.9,IF(E30="ILF",7.5,IF(E30="EIF",5.4)))))) -> 3.9
B31: 데이터 저장 | C31: 민원 텍스트 저장소 | D31: 민원 텍스트 데이터 저장 | E31: ILF | F31: =IF(E31="","",IF(E31="EI",4,IF(E31="EO",5.2,IF(E31="EQ",3.9,IF(E31="ILF",7.5,IF(E31="EIF",5.4)))))) -> 7.5
C32: OCR 이미지 저장소 | D32: OCR 변환 이미지 데이터 저장 | E32: ILF | F32: =IF(E32="","",IF(E32="EI",4,IF(E32="EO",5.2,IF(E32="EQ",3.9,IF(E32="ILF",7.5,IF(E32="EIF",5.4)))))) -> 7.5
C33: STT 음성 저장소 | D33: STT 전사 결과 저장 | E33: ILF | F33: =IF(E33="","",IF(E33="EI",4,IF(E33="EO",5.2,IF(E33="EQ",3.9,IF(E33="ILF",7.5,IF(E33="EIF",5.4)))))) -> 7.5
C34: 차량등록 데이터 저장소 | D34: 차량등록 행정데이터 저장 | E34: ILF | F34: =IF(E34="","",IF(E34="EI",4,IF(E34="EO",5.2,IF(E34="EQ",3.9,IF(E34="ILF",7.5,IF(E34="EIF",5.4)))))) -> 7.5
C35: 단속 데이터 저장소 | D35: 단속 행정데이터 저장 | E35: ILF | F35: =IF(E35="","",IF(E35="EI",4,IF(E35="EO",5.2,IF(E35="EQ",3.9,IF(E35="ILF",7.5,IF(E35="EIF",5.4)))))) -> 7.5
C36: GIS 데이터 저장소 | D36: GIS 공간정보 데이터 저장 | E36: ILF | F36: =IF(E36="","",IF(E36="EI",4,IF(E36="EO",5.2,IF(E36="EQ",3.9,IF(E36="ILF",7.5,IF(E36="EIF",5.4)))))) -> 7.5
C37: 외부데이터 저장소(기상청) | D37: 기상청 API 데이터 저장 | E37: ILF | F37: =IF(E37="","",IF(E37="EI",4,IF(E37="EO",5.2,IF(E37="EQ",3.9,IF(E37="ILF",7.5,IF(E37="EIF",5.4)))))) -> 7.5
C38: 외부데이터 저장소(112) | D38: 112 연계 데이터 저장 | E38: ILF | F38: =IF(E38="","",IF(E38="EI",4,IF(E38="EO",5.2,IF(E38="EQ",3.9,IF(E38="ILF",7.5,IF(E38="EIF",5.4)))))) -> 7.5
C39: 외부데이터 저장소(119) | D39: 119 연계 데이터 저장 | E39: ILF | F39: =IF(E39="","",IF(E39="EI",4,IF(E39="EO",5.2,IF(E39="EQ",3.9,IF(E39="ILF",7.5,IF(E39="EIF",5.4)))))) -> 7.5
C40: 표준 메타데이터 저장소 | D40: NGSI-LD 표준 메타데이터 저장 | E40: ILF | F40: =IF(E40="","",IF(E40="EI",4,IF(E40="EO",5.2,IF(E40="EQ",3.9,IF(E40="ILF",7.5,IF(E40="EIF",5.4)))))) -> 7.5
...

Sheet 02.데이터 전처리 용역
A1: 데이터 전처리 개발 용역
K2: (소프트웨어사업 대가산정 가이드, 24.05.13. (FP방식-간이법), KOSA)
A4: ○ 개발원가 산정 | J4: (단위 : 원)
A5: 총기능점수 | C5: 기능점수당 단가 | E5: 보정계수 | J5: 개발원가 | K5: 비고
E6: 규모 | F6: 연계복잡성 | G6: 성능 | H6: 다중사이트 | I6: 보안성
A7: =I31 -> 351 | C7: 605784 | E7: =J22 -> 1.28 | F7: =J23 -> 1.06 | G7: =J24 -> 1 | H7: =J25 -> 1 | I7: =J26 -> 1 | J7: =PRODUCT(A7:I7) -> 2.8849663e+08
A8: 합계(보정 후 개발원가) | J8: =SUM(J7:K7) -> 2.8849663e+08
A9: 기업이윤 | I9: 0.195 | J9: =J8*I9 -> 56256844
A10: 직접경비 | J10: -7208000
A11: 소프트웨어 개발비(부가세 별도) | J11: =J8+J9+J10 -> 3.3754548e+08
A12: 소프트웨어 개발비(부가세 포함, 10만원 이하 절사) | J12: =ROUNDDOWN(J11*1.1, -5) -> 371300000
A14: ○ 직접경비 | J14: (단위 : 원)
A15: 구분 | C15: 산출내역 | J15: 금액
A18: 합 계 | J18: =SUM(J16:K17) -> 0
A20: ○ 보정계수 산정
A21: 보정계수 구분 | C21: 복잡도 및 난이도 수준 | J21: 보정계수
A22: SW규모 | C22: ="= 0.4057 x (log e("&A7&") - 7.1978)^2 + 0.8878 (단, 500FP 미만 1.28, 3,000FP 초과 1.153 적용)" -> = 0.4057 x (log e(351) - 7.1978)^2 + 0.8878 (단, 500FP 미만 1.28, 3,000FP 초과 1.153 적용) | J22: =IF(A7<500,1.28,IF(A7>3000,1.153,0.4057*(LN(A7)-7.1978)^2+0.8878)) -> 1.28
A23: 연계복잡성 | C23: 4. 6~10개의 타 기관 연계 | J23: =VLOOKUP(C23,M23:N27,2,1) -> 1.06 | M23: 1. 타 기관 연계 없음 | N23: 0.88
A24: 성능 요구수준 | C24: 3. 응답시간이나 처리율이 피크타임(peak time)에 중요하며, 처리 시한이 명시되어 있다. | J24: =VLOOKUP(C24,M28:N32,2,1) -> 1 | M24: 2. 1~2개의 타 기관 연계 | N24: 0.94
A25: 다중사이트 운영성 | C25: 2. 다중사이트 운영성에 대한 요구사항이 있으며, 동일 하드웨어 및 소프트웨어 환경에서 운영되도록 설계된다. | J25: =VLOOKUP(C25,M33:N37,2,1) -> 1 | M25: 3. 3~5개의 타 기관 연계 | N25: 1
A26: 보안성 요구수준 | C26: 2. 위의 4가지 항목 중 2가지 요구사항이 포함되어 있다. | J26: =VLOOKUP(C26,M38:N42,2,1) -> 1 | M26: 4. 6~10개의 타 기관 연계 | N26: 1.06
M27: 5. 10개 초과의 타 기관 연계 | N27: 1.12
A28: ○ FP 집계 | M28: 1. 응답성능에 대한 특별한 요구사항이 없다. | N28: 0.91
A29: 구분 | D29: ILF | E29: EIF | F29: EI | G29: EO | H29: EQ | I29: 계 | M29: 2. 응답성능에 대한 요구사항이 있으나 특별한 조치가 필요하지는 않다. | N29: 0.95
A30: 기능수 | D30: =COUNTIF('02.데이터 전처리 FP산정'!E4:E70,"ILF") -> 20 | E30: =COUNTIF('02.데이터 전처리 FP산정'!E4:E70,"EIF") -> 0 | F30: =COUNTIF('02.데이터 전처리 FP산정'!E4:E70,"EI") -> 8 | G30: =COUNTIF('02.데이터 전처리 FP산정'!E4:E70,"EO") -> 22 | H30: =COUNTIF('02.데이터 전처리 FP산정'!E4:E70,"EQ") -> 14 | I30: =SUM(D30:H30) -> 64 | M30: 3. 응답시간이나 처리율이 피크타임(peak time)에 중요하며, 처리 시한이 명시되어 있다. | N30: 1
A31: 기능점수 | D31: =SUMIF('02.데이터 전처리 FP산정'!E4:E70,"ILF",'02.데이터 전처리 FP산정'!$F4:$F70) -> 150 | E31: =SUMIF('02.데이터 전처리 FP산정'!E4:E70,"EIF",'02.데이터 전처리 FP산정'!$F4:$F70) -> 0 | F31: =SUMIF('02.데이터 전처리 FP산정'!E4:E70,"EI",'02.데이터 전처리 FP산정'!$F4:$F70) -> 32 | G31: =SUMIF('02.데이터 전처리 FP산정'!E4:E70,"EO",'02.데이터 전처리 FP산정'!$F4:$F70) -> 114.4 | H31: =SUMIF('02.데이터 전처리 FP산정'!E4:E70,"EQ",'02.데이터 전처리 FP산정'!$F4:$F70) -> 54.6 | I31: =SUM(D31:H31) -> 351 | M31: 4. 응답시간이나 처리율이 모든 업무시간에 중요하며, 처리 시한이 명시되어 있다. | N31: 1.05
A32: 비중 | D32: =IF($I$31>0,D31/$I$31,"-") -> 0.42735043 | E32: =IF($I$31>0,E31/$I$31,"-") -> 0 | F32: =IF($I$31>0,F31/$I$31,"-") -> 0.091168091 | G32: =IF($I$31>0,G31/$I$31,"-") -> 0.32592593 | H32: =IF($I$31>0,H31/$I$31,"-") -> 0.15555556 | I32: =SUM(D32:H32) -> 1 | M32: 5. 응답성능 요구수준이 엄격하여, 설계, 개발 또는 구현 단계에서 성능 분석도구 사용이 필요하다. | N32: 1.09
M33: 1. 다중사이트 운영성에 대한 요구사항이 없다. | N33: 0.94
M34: 2. 다중사이트 운영성에 대한 요구사항이 있으며, 동일 하드웨어 및 소프트웨어 환경에서 운영되도록 설계된다. | N34: 1
M35: 3. 다중사이트 운영성에 대한 요구사항이 있으며, 유사 하드웨어 및 소프트웨어 환경에서 운영되도록 설계된다. | N35: 1.06
M36: 4. 다중사이트 운영성에 대한 요구사항이 있으며, 이질적인 하드웨어 및 소프트웨어 환경에서 운영되도록 설계된다. | N36: 1.13
M37: 5. 항목 4에 더하여 일반적 산출물 이외에 다중사이트에서 원활한 운영을 보장하기 위한 운영 절차의 문서화와 사전 모의훈련이 요구된다. | N37: 1.19
M38: 1. 암호화, 웹취약점 점검, 시큐어코딩, 개인정보보호 중 1가지 요구사항이 포함되어 있다. | N38: 0.97
M39: 2. 위의 4가지 항목 중 2가지 요구사항이 포함되어 있다. | N39: 1
M40: 3. 위의 4가지 항목 중 3가지 요구사항이 포함되어 있다. | N40: 1.03
M41: 4. 위의 4가지 항목이 모두 포함되어 있다. | N41: 1.06
M42: 5. 항목 4)에 더하여 추가적인 요구사항이 있다. | N42: 1.08
A44: FP산정
A45: FP산정

Sheet 02.데이터 전처리 FP산정
A1: 데이터 전처리 기능점수
A2: 기능명 | E2: 데이터 및 트랜잭션 기능 | F2: FP 산출 | G2: 비고
A3: ①어플리 케이션명 | B3: ②세부 업무명 | C3: ③단위프로세스명 | D3: 단위프로세스 설명 | E3: ④FP유형 | F3: ⑤가중치
A4: 실증관련 데이터허브 고도화 | B4: OCR 처리 | C4: OCR 템플릿/사전 저장 | D4: 문서 유형별 템플릿·사전 저장 | E4: ILF | F4: =IF(E4="","",IF(E4="EI",4,IF(E4="EO",5.2,IF(E4="EQ",3.9,IF(E4="ILF",7.5,IF(E4="EIF",5.4)))))) -> 7.5
C5: 다국어 폰트/문자셋 라이브러리 저장 | D5: 다국어 OCR 지원용 폰트/사전 저장 | E5: ILF | F5: =IF(E5="","",IF(E5="EI",4,IF(E5="EO",5.2,IF(E5="EQ",3.9,IF(E5="ILF",7.5,IF(E5="EIF",5.4)))))) -> 7.5
C6: 텍스트 추출 결과 출력 | D6: 스캔 PDF·이미지 → 텍스트 추출 | E6: EO | F6: =IF(E6="","",IF(E6="EI",4,IF(E6="EO",5.2,IF(E6="EQ",3.9,IF(E6="ILF",7.5,IF(E6="EIF",5.4)))))) -> 5.2
C7: 도면/표 추출 결과 출력 | D7: 표·도면 내 텍스트 별도 추출 결과 제공 | E7: EO | F7: =IF(E7="","",IF(E7="EI",4,IF(E7="EO",5.2,IF(E7="EQ",3.9,IF(E7="ILF",7.5,IF(E7="EIF",5.4)))))) -> 5.2
C8: 이미지 객체탐지 텍스트 분리 출력 | D8: 객체탐지 기반 텍스트 분리 출력 | E8: EO | F8: =IF(E8="","",IF(E8="EI",4,IF(E8="EO",5.2,IF(E8="EQ",3.9,IF(E8="ILF",7.5,IF(E8="EIF",5.4)))))) -> 5.2
C9: 변환 품질 검증 조회 | D9: OCR 정확도·오류 검증 리포트 | E9: EQ | F9: =IF(E9="","",IF(E9="EI",4,IF(E9="EO",5.2,IF(E9="EQ",3.9,IF(E9="ILF",7.5,IF(E9="EIF",5.4)))))) -> 3.9
C10: 문서별 품질 통계 조회 | D10: 문서별 성공/실패율 통계 조회 | E10: EQ | F10: =IF(E10="","",IF(E10="EI",4,IF(E10="EO",5.2,IF(E10="EQ",3.9,IF(E10="ILF",7.5,IF(E10="EIF",5.4)))))) -> 3.9
C11: OCR 모델 파라미터 저장 | D11: 모델 옵션/스코어링 기준 저장 | E11: ILF | F11: =IF(E11="","",IF(E11="EI",4,IF(E11="EO",5.2,IF(E11="EQ",3.9,IF(E11="ILF",7.5,IF(E11="EIF",5.4)))))) -> 7.5
C12: 필드 추출 매핑 저장소 | D12: 문서 필드-엔티티 매핑 규칙 저장 | E12: ILF | F12: =IF(E12="","",IF(E12="EI",4,IF(E12="EO",5.2,IF(E12="EQ",3.9,IF(E12="ILF",7.5,IF(E12="EIF",5.4)))))) -> 7.5
C13: 문서 유형 자동 분류 출력 | D13: 문서/양식 자동 분류 결과 | E13: EO | F13: =IF(E13="","",IF(E13="EI",4,IF(E13="EO",5.2,IF(E13="EQ",3.9,IF(E13="ILF",7.5,IF(E13="EIF",5.4)))))) -> 5.2
C14: 스캔 전처리 출력 | D14: 기울기 보정·노이즈 제거 결과 | E14: EO | F14: =IF(E14="","",IF(E14="EI",4,IF(E14="EO",5.2,IF(E14="EQ",3.9,IF(E14="ILF",7.5,IF(E14="EIF",5.4)))))) -> 5.2
C15: 테이블 구조 복원 출력 | D15: 셀 경계/병합 복원 결과 | E15: EO | F15: =IF(E15="","",IF(E15="EI",4,IF(E15="EO",5.2,IF(E15="EQ",3.9,IF(E15="ILF",7.5,IF(E15="EIF",5.4)))))) -> 5.2
C16: 레이아웃 분석 출력 | D16: 헤더/푸터/본문/주석 레이아웃 추출 | E16: EO | F16: =IF(E16="","",IF(E16="EI",4,IF(E16="EO",5.2,IF(E16="EQ",3.9,IF(E16="ILF",7.5,IF(E16="EIF",5.4)))))) -> 5.2
... C23: 품질 개선 피드백 저장 | D23: 검수 피드백/수정 이력 저장 | E23: ILF | F23: =IF(E23="","",IF(E23="EI",4,IF(E23="EO",5.2,IF(E23="EQ",3.9,IF(E23="ILF",7.5,IF(E23="EIF",5.4)))))) -> 7.5
B24: RPA 수집 | C24: 수집 시나리오 정의 저장 | D24: 포털·콜센터 RPA 시나리오 저장 | E24: ILF | F24: =IF(E24="","",IF(E24="EI",4,IF(E24="EO",5.2,IF(E24="EQ",3.9,IF(E24="ILF",7.5,IF(E24="EIF",5.4)))))) -> 7.5
C25: 계정/세션 관리 정책 저장 | D25: 로그인 계정/세션 정책 저장 | E25: ILF | F25: =IF(E25="","",IF(E25="EI",4,IF(E25="EO",5.2,IF(E25="EQ",3.9,IF(E25="ILF",7.5,IF(E25="EIF",5.4)))))) -> 7.5
C26: 수집 플로우 실행 | D26: 포털 자동 로그인·데이터 다운로드 | E26: EI | F26: =IF(E26="","",IF(E26="EI",4,IF(E26="EO",5.2,IF(E26="EQ",3.9,IF(E26="ILF",7.5,IF(E26="EIF",5.4)))))) -> 4
C27: 스케줄링/트리거 실행 | D27: 예약 실행·조건부 트리거 | E27: EI | F27: =IF(E27="","",IF(E27="EI",4,IF(E27="EO",5.2,IF(E27="EQ",3.9,IF(E27="ILF",7.5,IF(E27="EIF",5.4)))))) -> 4
C28: 재시도 실행 | D28: 장애 발생 시 자동 재시도 | E28: EI | F28: =IF(E28="","",IF(E28="EI",4,IF(E28="EO",5.2,IF(E28="EQ",3.9,IF(E28="ILF",7.5,IF(E28="EIF",5.4)))))) -> 4
C29: 실행 로그 검증 | D29: 성공/실패 로그 검증 | E29: EQ | F29: =IF(E29="","",IF(E29="EI",4,IF(E29="EO",5.2,IF(E29="EQ",3.9,IF(E29="ILF",7.5,IF(E29="EIF",5.4)))))) -> 3.9
C30: 프로세스별 리포트 조회 | D30: 수집별 성공률/실패율 통계 | E30: EQ | F30: =IF(E30="","",IF(E30="EI",4,IF(E30="EO",5.2,IF(E30="EQ",3.9,IF(E30="ILF",7.5,IF(E30="EIF",5.4)))))) -> 3.9
C31: 크리덴셜 금고 저장 | D31: 자격증명/키 보관·로테이션 정책 | E31: ILF | F31: =IF(E31="","",IF(E31="EI",4,IF(E31="EO",5.2,IF(E31="EQ",3.9,IF(E31="ILF",7.5,IF(E31="EIF",5.4)))))) -> 7.5
C32: 스케줄/트리거 정책 저장 | D32: 캘린더·예외일·재발 스케줄 정책 | E32: ILF | F32: =IF(E32="","",IF(E32="EI",4,IF(E32="EO",5.2,IF(E32="EQ",3.9,IF(E32="ILF",7.5,IF(E32="EIF",5.4)))))) -> 7.5
C33: 예외 패턴 룰 저장 | D33: 에러코드/화면변경 룰셋 | E33: ILF | F33: =IF(E33="","",IF(E33="EI",4,IF(E33="EO",5.2,IF(E33="EQ",3.9,IF(E33="ILF",7.5,IF(E33="EIF",5.4)))))) -> 7.5
C34: Captcha/OTP 처리 | D34: 2단계 인증 자동처리 | E34: EI | F34: =IF(E34="","",IF(E34="EI",4,IF(E34="EO",5.2,IF(E34="EQ",3.9,IF(E34="ILF",7.5,IF(E34="EIF",5.4)))))) -> 4
C35: 파일 업/다운로드 처리 | D35: 대용량 파일 전송/검증 | E35: EI | F35: =IF(E35="","",IF(E35="EI",4,IF(E35="EO",5.2,IF(E35="EQ",3.9,IF(E35="ILF",7.5,IF(E35="EIF",5.4)))))) -> 4
C36: API+RPA 하이브리드 처리 | D36: API/스크린 스크래핑 혼합 | E36: EI | F36: =IF(E36="","",IF(E36="EI",4,IF(E36="EO",5.2,IF(E36="EQ",3.9,IF(E36="ILF",7.5,IF(E36="EIF",5.4)))))) -> 4
... C43: 프록시/헤더 변조 처리 | D43: 우회·헤더 관리 자동화 | E43: EI | F43: =IF(E43="","",IF(E43="EI",4,IF(E43="EO",5.2,IF(E43="EQ",3.9,IF(E43="ILF",7.5,IF(E43="EIF",5.4)))))) -> 4
B44: STT 처리 | C44: 도메인 사전/모델 저장 | D44: 사투리·생활언어·도메인 모델 저장 | E44: ILF | F44: =IF(E44="","",IF(E44="EI",4,IF(E44="EO",5.2,IF(E44="EQ",3.9,IF(E44="ILF",7.5,IF(E44="EIF",5.4)))))) -> 7.5
C45: 사용자 커스텀 사전 저장 | D45: 사용자 정의 용어사전 저장 | E45: ILF | F45: =IF(E45="","",IF(E45="EI",4,IF(E45="EO",5.2,IF(E45="EQ",3.9,IF(E45="ILF",7.5,IF(E45="EIF",5.4)))))) -> 7.5
C46: 녹취 텍스트 변환 출력 | D46: 콜센터 음성 → 텍스트 변환 | E46: EO | F46: =IF(E46="","",IF(E46="EI",4,IF(E46="EO",5.2,IF(E46="EQ",3.9,IF(E46="ILF",7.5,IF(E46="EIF",5.4)))))) -> 5.2
C47: 발화자 분리 결과 출력 | D47: 화자 분리(Diarization) 결과 | E47: EO | F47: =IF(E47="","",IF(E47="EI",4,IF(E47="EO",5.2,IF(E47="EQ",3.9,IF(E47="ILF",7.5,IF(E47="EIF",5.4)))))) -> 5.2
C48: 개인정보 마스킹 출력 | D48: 전화번호·이름 마스킹 | E48: EO | F48: =IF(E48="","",IF(E48="EI",4,IF(E48="EO",5.2,IF(E48="EQ",3.9,IF(E48="ILF",7.5,IF(E48="EIF",5.4)))))) -> 5.2
C49: WER 성능 리포트 조회 | D49: WER 기반 성능 지표 | E49: EQ | F49: =IF(E49="","",IF(E49="EI",4,IF(E49="EO",5.2,IF(E49="EQ",3.9,IF(E49="ILF",7.5,IF(E49="EIF",5.4)))))) -> 3.9
C50: 발화자별 성능 리포트 조회 | D50: 화자별 정확도/시간 분석 | E50: EQ | F50: =IF(E50="","",IF(E50="EI",4,IF(E50="EO",5.2,IF(E50="EQ",3.9,IF(E50="ILF",7.5,IF(E50="EIF",5.4)))))) -> 3.9
C51: 언어/사투리 패킷 저장 | D51: 방언/발음 변이 패킷 저장 | E51: ILF | F51: =IF(E51="","",IF(E51="EI",4,IF(E51="EO",5.2,IF(E51="EQ",3.9,IF(E51="ILF",7.5,IF(E51="EIF",5.4)))))) -> 7.5
C52: 커스텀 음향모델 설정 저장 | D52: 노이즈/마이크 특성 보정 설정 | E52: ILF | F52: =IF(E52="","",IF(E52="EI",4,IF(E52="EO",5.2,IF(E52="EQ",3.9,IF(E52="ILF",7.5,IF(E52="EIF",5.4)))))) -> 7.5
...

Sheet 03.데이터 분석 기능 개발 용역
A1: 이벤트 데이터 분석 개발 용역
K2: (소프트웨어사업 대가산정 가이드, 24.05.13. (FP방식-간이법), KOSA)
A4: ○ 개발원가 산정 | J4: (단위 : 원)
A5: 총기능점수 | C5: 기능점수당 단가 | E5: 보정계수 | J5: 개발원가 | K5: 비고
E6: 규모 | F6: 연계복잡성 | G6: 성능 | H6: 다중사이트 | I6: 보안성
A7: =I31 -> 118.2 | C7: 605784 | E7: =J22 -> 1.28 | F7: =J23 -> 1.06 | G7: =J24 -> 1 | H7: =J25 -> 1 | I7: =J26 -> 1 | J7: =PRODUCT(A7:I7) -> 97151858
A8: 합계(보정 후 개발원가) | J8: =SUM(J7:K7) -> 97151858
A9: 기업이윤 | I9: 0.195 | J9: =J8*I9 -> 18944612
A10: 직접경비 | J10: -2641000
A11: 소프트웨어 개발비(부가세 별도) | J11: =J8+J9+J10 -> 1.1345547e+08
A12: 소프트웨어 개발비(부가세 포함, 10만원 이하 절사) | J12: =ROUNDDOWN(J11*1.1, -5) -> 124800000
A14: ○ 직접경비 | J14: (단위 : 원)
A15: 구분 | C15: 산출내역 | J15: 금액
A18: 합 계 | J18: =SUM(J16:K17) -> 0
A20: ○ 보정계수 산정
A21: 보정계수 구분 | C21: 복잡도 및 난이도 수준 | J21: 보정계수
A22: SW규모 | C22: ="= 0.4057 x (log e("&A7&") - 7.1978)^2 + 0.8878 (단, 500FP 미만 1.28, 3,000FP 초과 1.153 적용)" -> = 0.4057 x (log e(118.2) - 7.1978)^2 + 0.8878 (단, 500FP 미만 1.28, 3,000FP 초과 1.153 적용) | J22: =IF(A7<500,1.28,IF(A7>3000,1.153,0.4057*(LN(A7)-7.1978)^2+0.8878)) -> 1.28
A23: 연계복잡성 | C23: 4. 6~10개의 타 기관 연계 | J23: =VLOOKUP(C23,M23:N27,2,1) -> 1.06 | M23: 1. 타 기관 연계 없음 | N23: 0.88
A24: 성능 요구수준 | C24: 3. 응답시간이나 처리율이 피크타임(peak time)에 중요하며, 처리 시한이 명시되어 있다. | J24: =VLOOKUP(C24,M28:N32,2,1) -> 1 | M24: 2. 1~2개의 타 기관 연계 | N24: 0.94
A25: 다중사이트 운영성 | C25: 2. 다중사이트 운영성에 대한 요구사항이 있으며, 동일 하드웨어 및 소프트웨어 환경에서 운영되도록 설계된다. | J25: =VLOOKUP(C25,M33:N37,2,1) -> 1 | M25: 3. 3~5개의 타 기관 연계 | N25: 1
A26: 보안성 요구수준 | C26: 2. 위의 4가지 항목 중 2가지 요구사항이 포함되어 있다. | J26: =VLOOKUP(C26,M38:N42,2,1) -> 1 | M26: 4. 6~10개의 타 기관 연계 | N26: 1.06
M27: 5. 10개 초과의 타 기관 연계 | N27: 1.12
A28: ○ FP 집계 | M28: 1. 응답성능에 대한 특별한 요구사항이 없다. | N28: 0.91
A29: 구분 | D29: ILF | E29: EIF | F29: EI | G29: EO | H29: EQ | I29: 계 | M29: 2. 응답성능에 대한 요구사항이 있으나 특별한 조치가 필요하지는 않다. | N29: 0.95
A30: 기능수 | D30: =COUNTIF('04.데이터 분석 기능 FP산정'!E4:E76,"ILF") -> 6 | E30: =COUNTIF('04.데이터 분석 기능 FP산정'!E4:E76,"EIF") -> 0 | F30: =COUNTIF('04.데이터 분석 기능 FP산정'!E4:E76,"EI") -> 4 | G30: =COUNTIF('04.데이터 분석 기능 FP산정'!E4:E76,"EO") -> 8 | H30: =COUNTIF('04.데이터 분석 기능 FP산정'!E4:E76,"EQ") -> 4 | I30: =SUM(D30:H30) -> 22 | M30: 3. 응답시간이나 처리율이 피크타임(peak time)에 중요하며, 처리 시한이 명시되어 있다. | N30: 1
A31: 기능점수 | D31: =SUMIF('04.데이터 분석 기능 FP산정'!E4:E76,"ILF",'04.데이터 분석 기능 FP산정'!$F4:$F76) -> 45 | E31: =SUMIF('04.데이터 분석 기능 FP산정'!E4:E76,"EIF",'04.데이터 분석 기능 FP산정'!$F4:$F76) -> 0 | F31: =SUMIF('04.데이터 분석 기능 FP산정'!E4:E76,"EI",'04.데이터 분석 기능 FP산정'!$F4:$F76) -> 16 | G31: =SUMIF('04.데이터 분석 기능 FP산정'!E4:E76,"EO",'04.데이터 분석 기능 FP산정'!$F4:$F76) -> 41.6 | H31: =SUMIF('04.데이터 분석 기능 FP산정'!E4:E76,"EQ",'04.데이터 분석 기능 FP산정'!$F4:$F76) -> 15.6 | I31: =SUM(D31:H31) -> 118.2 | M31: 4. 응답시간이나 처리율이 모든 업무시간에 중요하며, 처리 시한이 명시되어 있다. | N31: 1.05
A32: 비중 | D32: =IF($I$31>0,D31/$I$31,"-") -> 0.38071066 | E32: =IF($I$31>0,E31/$I$31,"-") -> 0 | F32: =IF($I$31>0,F31/$I$31,"-") -> 0.13536379 | G32: =IF($I$31>0,G31/$I$31,"-") -> 0.35194585 | H32: =IF($I$31>0,H31/$I$31,"-") -> 0.1319797 | I32: =SUM(D32:H32) -> 1 | M32: 5. 응답성능 요구수준이 엄격하여, 설계, 개발 또는 구현 단계에서 성능 분석도구 사용이 필요하다. | N32: 1.09
M33: 1. 다중사이트 운영성에 대한 요구사항이 없다. | N33: 0.94
M34: 2. 다중사이트 운영성에 대한 요구사항이 있으며, 동일 하드웨어 및 소프트웨어 환경에서 운영되도록 설계된다. | N34: 1
M35: 3. 다중사이트 운영성에 대한 요구사항이 있으며, 유사 하드웨어 및 소프트웨어 환경에서 운영되도록 설계된다. | N35: 1.06
M36: 4. 다중사이트 운영성에 대한 요구사항이 있으며, 이질적인 하드웨어 및 소프트웨어 환경에서 운영되도록 설계된다. | N36: 1.13
M37: 5. 항목 4에 더하여 일반적 산출물 이외에 다중사이트에서 원활한 운영을 보장하기 위한 운영 절차의 문서화와 사전 모의훈련이 요구된다. | N37: 1.19
M38: 1. 암호화, 웹취약점 점검, 시큐어코딩, 개인정보보호 중 1가지 요구사항이 포함되어 있다. | N38: 0.97
M39: 2. 위의 4가지 항목 중 2가지 요구사항이 포함되어 있다. | N39: 1
M40: 3. 위의 4가지 항목 중 3가지 요구사항이 포함되어 있다. | N40: 1.03
M41: 4. 위의 4가지 항목이 모두 포함되어 있다. | N41: 1.06
M42: 5. 항목 4)에 더하여 추가적인 요구사항이 있다. | N42: 1.08
A44: FP산정
A45: FP산정

Sheet 04.데이터 분석 기능 FP산정
A1: 이벤트 데이터 분석 기능점수
A2: 기능명 | E2: 데이터 및 트랜잭션 기능 | F2: FP 산출 | G2: 비고
A3: ①어플리 케이션명 | B3: ②세부 업무명 | C3: ③단위프로세스명 | D3: 단위프로세스 설명 | E3: ④FP유형 | F3: ⑤가중치
A4: 공영주차장 스마트 안전 AI 분석 솔루션 | B4: 이벤트 데이터 분석 | C4: 화재 이벤트 정의 저장소 | D4: 불꽃·연기 이벤트 유형 정의 저장 | E4: ILF | F4: =IF(E4="","",IF(E4="EI",4,IF(E4="EO",5.2,IF(E4="EQ",3.9,IF(E4="ILF",7.5,IF(E4="EIF",5.4)))))) -> 7.5
C5: 온도 이벤트 정의 저장소 | D5: 온도 이상 감시 규칙 저장 | E5: ILF | F5: =IF(E5="","",IF(E5="EI",4,IF(E5="EO",5.2,IF(E5="EQ",3.9,IF(E5="ILF",7.5,IF(E5="EIF",5.4)))))) -> 7.5
C6: 음향 이벤트 정의 저장소 | D6: 폭발·비명·차량파손 이벤트 정의 저장 | E6: ILF | F6: =IF(E6="","",IF(E6="EI",4,IF(E6="EO",5.2,IF(E6="EQ",3.9,IF(E6="ILF",7.5,IF(E6="EIF",5.4)))))) -> 7.5
C7: 경보 단계 정책 저장소 | D7: 주의/경계/심각 단계 정책 저장 | E7: ILF | F7: =IF(E7="","",IF(E7="EI",4,IF(E7="EO",5.2,IF(E7="EQ",3.9,IF(E7="ILF",7.5,IF(E7="EIF",5.4)))))) -> 7.5
C8: 알림 채널 정책 저장소 | D8: 앱/SMS/이메일/웹훅 채널 정책 저장 | E8: ILF | F8: =IF(E8="","",IF(E8="EI",4,IF(E8="EO",5.2,IF(E8="EQ",3.9,IF(E8="ILF",7.5,IF(E8="EIF",5.4)))))) -> 7.5
C9: 센서/카메라 메타데이터 저장소 | D9: 설치 위치·사양 저장 | E9: ILF | F9: =IF(E9="","",IF(E9="EI",4,IF(E9="EO",5.2,IF(E9="EQ",3.9,IF(E9="ILF",7.5,IF(E9="EIF",5.4)))))) -> 7.5
C10: 실시간 화재 이벤트 수집 | D10: 화재(불꽃·연기) 스트림 실시간 수집 | E10: EI | F10: =IF(E10="","",IF(E10="EI",4,IF(E10="EO",5.2,IF(E10="EQ",3.9,IF(E10="ILF",7.5,IF(E10="EIF",5.4)))))) -> 4
C11: 실시간 온도 이벤트 수집 | D11: 온도 센싱 이벤트 수집 | E11: EI | F11: =IF(E11="","",IF(E11="EI",4,IF(E11="EO",5.2,IF(E11="EQ",3.9,IF(E11="ILF",7.5,IF(E11="EIF",5.4)))))) -> 4
C12: 실시간 음향 이벤트 수집 | D12: 음향 스트림 수집 | E12: EI | F12: =IF(E12="","",IF(E12="EI",4,IF(E12="EO",5.2,IF(E12="EQ",3.9,IF(E12="ILF",7.5,IF(E12="EIF",5.4)))))) -> 4
C13: 이벤트 탐지 결과 출력(화재) | D13: 화재 탐지 결과 출력 | E13: EO | F13: =IF(E13="","",IF(E13="EI",4,IF(E13="EO",5.2,IF(E13="EQ",3.9,IF(E13="ILF",7.5,IF(E13="EIF",5.4)))))) -> 5.2
C14: 이벤트 탐지 결과 출력(온도) | D14: 온도 이상 탐지 결과 출력 | E14: EO | F14: =IF(E14="","",IF(E14="EI",4,IF(E14="EO",5.2,IF(E14="EQ",3.9,IF(E14="ILF",7.5,IF(E14="EIF",5.4)))))) -> 5.2
C15: 이벤트 탐지 결과 출력(음향) | D15: 폭발음·비명 등 탐지 결과 출력 | E15: EO | F15: =IF(E15="","",IF(E15="EI",4,IF(E15="EO",5.2,IF(E15="EQ",3.9,IF(E15="ILF",7.5,IF(E15="EIF",5.4)))))) -> 5.2
C16: 알림 출력(앱) | D16: 앱 푸시 알림 출력 | E16: EO | F16: =IF(E16="","",IF(E16="EI",4,IF(E16="EO",5.2,IF(E16="EQ",3.9,IF(E16="ILF",7.5,IF(E16="EIF",5.4)))))) -> 5.2
... C25: 품질 대시보드 조회 | D25: 탐지율·지연·신뢰도 대시보드 | E25: EQ | F25: =IF(E25="","",IF(E25="EI",4,IF(E25="EO",5.2,IF(E25="EQ",3.9,IF(E25="ILF",7.5,IF(E25="EIF",5.4)))))) -> 3.9
A26: * 기능점수 산정 참고 | F26: =SUM(F4:F24) -> 114.3
A27: * FP 유형 = EI (Exteranl Input : 외부입력) EO (External Output : 외부출력) EQ (External Inquiries : 외부조회)
A28: ILF (Internal Logical Files : 내부논리파일) EIF(Externa Interface Files : 외부연계 파일)
A30: * 용어설명
A31: *ILF : 사용자 관점에서 식별 가능한, 논리적으로 연관된 하나의 데이터그룹 또는 제어정보로서 측정대상 애플리케이션 내부에서 유지되는 파일
A32: *EIF : 사용자 관점에서 식별 가능한, 사용자가 식별할 수 있는 논리적으로 연관된 하나의 데이터그룹 또는 제어정보로서
A33: 측정대상 애플리케이션 내부에서는 오직 참조만 되고 다른 애플리케이션에서 유지되는 파일
A34: *EI : 애플리케이션 경계 밖에서 들어오는 데이터나 제어정보를 처리하는 단위 프로세스로서, 하나 이상의 논리파일을 변경하거나 시스템 동작을 변경함
A35: *EO : 데이터나 제어정보 애플리케이션 경계 밖의 사용자에게 보여주는단위프로세스로서, 데이터나 제어정보에 처리로직이 적용됨.
A36: 처리로직은 하나 이상의 수학적 계산, 공식 또는 파생 데이터를 포함하거나, 하나 이상의 내부논리파일(ILF)의 유지관리 작업이 발생하거나,
A37: 시스템의 동작 변경이 수반됨
A38: *EQ : 데이터나 제어정보를 애플리케이션 경계 밖으로 보여주는 단위프로세스로서, 데이터나 제어정보를 단순히 사용자에게 제공함.
A39: 외부조회는 수학적 계산이나 공식을 사용하지 않으며, 파생 데이터도 생성하지 않음.
A40: 처리 과정에서 내부논리파일(ILF)의 유지관리작업이 발생하지 않으며 시스템의 동작도 변경하지 않음
G41: =IF(F41="","",IF(F41="EI",4,IF(F41="EO",5.2,IF(F41="EQ",3.9,IF(F41="ILF",7.5,IF(F41="EIF",5.4))))))

Sheet 04. LLM 기반 자연어 처리 응용 기능 용역
A1: LLM 기반 자연어 처리 응용 기능 개발 용역
K2: (소프트웨어사업 대가산정 가이드, 24.05.13. (FP방식-간이법), KOSA)
A4: ○ 개발원가 산정 | J4: (단위 : 원)
A5: 총기능점수 | C5: 기능점수당 단가 | E5: 보정계수 | J5: 개발원가 | K5: 비고
E6: 규모 | F6: 연계복잡성 | G6: 성능 | H6: 다중사이트 | I6: 보안성
A7: =I31 -> 697.4 | C7: 605784 | E7: =J22 -> 1.0594408 | F7: =J23 -> 1.06 | G7: =J24 -> 1 | H7: =J25 -> 1 | I7: =J26 -> 1 | J7: =PRODUCT(A7:I7) -> 4.7444112e+08
A8: 합계(보정 후 개발원가) | J8: =SUM(J7:K7) -> 4.7444112e+08
A9: 기업이윤 | I9: 0.195 | J9: =J8*I9 -> 92516018
A10: 직접경비 | J10: -13593000
A11: 소프트웨어 개발비(부가세 별도) | J11: =J8+J9+J10 -> 5.5336413e+08
A12: 소프트웨어 개발비(부가세 포함, 10만원 이하 절사) | J12: =ROUNDDOWN(J11*1.1, -5) -> 608700000
A14: ○ 직접경비 | J14: (단위 : 원)
A15: 구분 | C15: 산출내역 | J15: 금액
A18: 합 계 | J18: =SUM(J16:K17) -> 0
A20: ○ 보정계수 산정
A21: 보정계수 구분 | C21: 복잡도 및 난이도 수준 | J21: 보정계수
A22: SW규모 | C22: ="= 0.4057 x (log e("&A7&") - 7.1978)^2 + 0.8878 (단, 500FP 미만 1.28, 3,000FP 초과 1.153 적용)" -> = 0.4057 x (log e(697.399999999999) - 7.1978)^2 + 0.8878 (단, 500FP 미만 1.28, 3,000FP 초과 1.153 적용) | J22: =IF(A7<500,1.28,IF(A7>3000,1.153,0.4057*(LN(A7)-7.1978)^2+0.8878)) -> 1.0594408
A23: 연계복잡성 | C23: 4. 6~10개의 타 기관 연계 | J23: =VLOOKUP(C23,M23:N27,2,1) -> 1.06 | M23: 1. 타 기관 연계 없음 | N23: 0.88
A24: 성능 요구수준 | C24: 3. 응답시간이나 처리율이 피크타임(peak time)에 중요하며, 처리 시한이 명시되어 있다. | J24: =VLOOKUP(C24,M28:N32,2,1) -> 1 | M24: 2. 1~2개의 타 기관 연계 | N24: 0.94
A25: 다중사이트 운영성 | C25: 2. 다중사이트 운영성에 대한 요구사항이 있으며, 동일 하드웨어 및 소프트웨어 환경에서 운영되도록 설계된다. | J25: =VLOOKUP(C25,M33:N37,2,1) -> 1 | M25: 3. 3~5개의 타 기관 연계 | N25: 1
A26: 보안성 요구수준 | C26: 2. 위의 4가지 항목 중 2가지 요구사항이 포함되어 있다. | J26: =VLOOKUP(C26,M38:N42,2,1) -> 1 | M26: 4. 6~10개의 타 기관 연계 | N26: 1.06
M27: 5. 10개 초과의 타 기관 연계 | N27: 1.12
A28: ○ FP 집계 | M28: 1. 응답성능에 대한 특별한 요구사항이 없다. | N28: 0.91
A29: 구분 | D29: ILF | E29: EIF | F29: EI | G29: EO | H29: EQ | I29: 계 | M29: 2. 응답성능에 대한 요구사항이 있으나 특별한 조치가 필요하지는 않다. | N29: 0.95
A30: 기능수 | D30: =COUNTIF('04.LLM 기반 자연어 처리 응용 기능 산정'!E4:E184,"ILF") -> 24 | E30: =COUNTIF('04.LLM 기반 자연어 처리 응용 기능 산정'!E4:E184,"EIF") -> 0 | F30: =COUNTIF('04.LLM 기반 자연어 처리 응용 기능 산정'!E4:E184,"EI") -> 0 | G30: =COUNTIF('04.LLM 기반 자연어 처리 응용 기능 산정'!E4:E184,"EO") -> 83 | H30: =COUNTIF('04.LLM 기반 자연어 처리 응용 기능 산정'!E4:E184,"EQ") -> 22 | I30: =SUM(D30:H30) -> 129 | M30: 3. 응답시간이나 처리율이 피크타임(peak time)에 중요하며, 처리 시한이 명시되어 있다. | N30: 1
A31: 기능점수 | D31: =SUMIF('04.LLM 기반 자연어 처리 응용 기능 산정'!E4:E184,"ILF",'04.LLM 기반 자연어 처리 응용 기능 산정'!$F4:$F184) -> 180 | E31: =SUMIF('04.LLM 기반 자연어 처리 응용 기능 산정'!E4:E184,"EIF",'04.LLM 기반 자연어 처리 응용 기능 산정'!$F4:$F184) -> 0 | F31: =SUMIF('04.LLM 기반 자연어 처리 응용 기능 산정'!E4:E184,"EI",'04.LLM 기반 자연어 처리 응용 기능 산정'!$F4:$F184) -> 0 | G31: =SUMIF('04.LLM 기반 자연어 처리 응용 기능 산정'!E4:E184,"EO",'04.LLM 기반 자연어 처리 응용 기능 산정'!$F4:$F184) -> 431.6 | H31: =SUMIF('04.LLM 기반 자연어 처리 응용 기능 산정'!E4:E184,"EQ",'04.LLM 기반 자연어 처리 응용 기능 산정'!$F4:$F184) -> 85.8 | I31: =SUM(D31:H31) -> 697.4 | M31: 4. 응답시간이나 처리율이 모든 업무시간에 중요하며, 처리 시한이 명시되어 있다. | N31: 1.05
A32: 비중 | D32: =IF($I$31>0,D31/$I$31,"-") -> 0.25810152 | E32: =IF($I$31>0,E31/$I$31,"-") -> 0 | F32: =IF($I$31>0,F31/$I$31,"-") -> 0 | G32: =IF($I$31>0,G31/$I$31,"-") -> 0.61887009 | H32: =IF($I$31>0,H31/$I$31,"-") -> 0.12302839 | I32: =SUM(D32:H32) -> 1 | M32: 5. 응답성능 요구수준이 엄격하여, 설계, 개발 또는 구현 단계에서 성능 분석도구 사용이 필요하다. | N32: 1.09
M33: 1. 다중사이트 운영성에 대한 요구사항이 없다. | N33: 0.94
M34: 2. 다중사이트 운영성에 대한 요구사항이 있으며, 동일 하드웨어 및 소프트웨어 환경에서 운영되도록 설계된다. | N34: 1
M35: 3. 다중사이트 운영성에 대한 요구사항이 있으며, 유사 하드웨어 및 소프트웨어 환경에서 운영되도록 설계된다. | N35: 1.06
M36: 4. 다중사이트 운영성에 대한 요구사항이 있으며, 이질적인 하드웨어 및 소프트웨어 환경에서 운영되도록 설계된다. | N36: 1.13
M37: 5. 항목 4에 더하여 일반적 산출물 이외에 다중사이트에서 원활한 운영을 보장하기 위한 운영 절차의 문서화와 사전 모의훈련이 요구된다. | N37: 1.19
M38: 1. 암호화, 웹취약점 점검, 시큐어코딩, 개인정보보호 중 1가지 요구사항이 포함되어 있다. | N38: 0.97
M39: 2. 위의 4가지 항목 중 2가지 요구사항이 포함되어 있다. | N39: 1
M40: 3. 위의 4가지 항목 중 3가지 요구사항이 포함되어 있다. | N40: 1.03
M41: 4. 위의 4가지 항목이 모두 포함되어 있다. | N41: 1.06
M42: 5. 항목 4)에 더하여 추가적인 요구사항이 있다. | N42: 1.08
A44: FP산정
A45: FP산정

Sheet 04.LLM 기반 자연어 처리 응용 기능 산정
A1: LLM 기반 자연어 처리 응용 기능점수
A2: 기능명 | E2: 데이터 및 트랜잭션 기능 | F2: FP 산출 | G2: 비고
A3: ①어플리 케이션명 | B3: ②세부 업무명 | C3: ③단위프로세스명 | D3: 단위프로세스 설명 | E3: ④FP유형 | F3: ⑤가중치
A4: 공영주차장 스마트 안전 AI 분석 솔루션 | B4: LLM 생성 | C4: 프롬프트 템플릿 저장소 | D4: 도메인/업무별 템플릿, 버전, 승인상태 저장 | E4: ILF | F4: =IF(E4="","",IF(E4="EI",4,IF(E4="EO",5.2,IF(E4="EQ",3.9,IF(E4="ILF",7.5,IF(E4="EIF",5.4)))))) -> 7.5
C5: 응답 스키마 레지스트리 | D5: JSON 스키마/필수 필드/검증 규칙 저장 | E5: ILF | F5: =IF(E5="","",IF(E5="EI",4,IF(E5="EO",5.2,IF(E5="EQ",3.9,IF(E5="ILF",7.5,IF(E5="EIF",5.4)))))) -> 7.5
C6: 가이드·컴플라이언스 규칙 저장 | D6: 기관 규정, 금칙어/허용어, 검증 규칙 저장 | E6: ILF | F6: =IF(E6="","",IF(E6="EI",4,IF(E6="EO",5.2,IF(E6="EQ",3.9,IF(E6="ILF",7.5,IF(E6="EIF",5.4)))))) -> 7.5
C7: 톤/스타일 설정 저장 | D7: 시민친화/전문가/두괄식/간결체 등 스타일 설정 저장 | E7: ILF | F7: =IF(E7="","",IF(E7="EI",4,IF(E7="EO",5.2,IF(E7="EQ",3.9,IF(E7="ILF",7.5,IF(E7="EIF",5.4)))))) -> 7.5
C8: A/B 실험/롤백 설정 저장 | D8: 실험군/대조군, 릴리즈/롤백 메타 저장 | E8: ILF | F8: =IF(E8="","",IF(E8="EI",4,IF(E8="EO",5.2,IF(E8="EQ",3.9,IF(E8="ILF",7.5,IF(E8="EIF",5.4)))))) -> 7.5
C9: 민원답변문 생성(표준) | D9: 민원답변문 표준 스타일 자동 생성 | E9: EO | F9: =IF(E9="","",IF(E9="EI",4,IF(E9="EO",5.2,IF(E9="EQ",3.9,IF(E9="ILF",7.5,IF(E9="EIF",5.4)))))) -> 5.2
C10: 민원답변문 생성(시민친화) | D10: 민원답변문 시민친화 스타일 자동 생성 | E10: EO | F10: =IF(E10="","",IF(E10="EI",4,IF(E10="EO",5.2,IF(E10="EQ",3.9,IF(E10="ILF",7.5,IF(E10="EIF",5.4)))))) -> 5.2
C11: 민원답변문 생성(전문가톤) | D11: 민원답변문 전문가톤 스타일 자동 생성 | E11: EO | F11: =IF(E11="","",IF(E11="EI",4,IF(E11="EO",5.2,IF(E11="EQ",3.9,IF(E11="ILF",7.5,IF(E11="EIF",5.4)))))) -> 5.2
C12: 민원답변문 생성(두괄식) | D12: 민원답변문 두괄식 스타일 자동 생성 | E12: EO | F12: =IF(E12="","",IF(E12="EI",4,IF(E12="EO",5.2,IF(E12="EQ",3.9,IF(E12="ILF",7.5,IF(E12="EIF",5.4)))))) -> 5.2
C13: 민원답변문 생성(양식화) | D13: 민원답변문 양식화 스타일 자동 생성 | E13: EO | F13: =IF(E13="","",IF(E13="EI",4,IF(E13="EO",5.2,IF(E13="EQ",3.9,IF(E13="ILF",7.5,IF(E13="EIF",5.4)))))) -> 5.2
C14: 정책보고문 생성(표준) | D14: 정책보고문 표준 스타일 자동 생성 | E14: EO | F14: =IF(E14="","",IF(E14="EI",4,IF(E14="EO",5.2,IF(E14="EQ",3.9,IF(E14="ILF",7.5,IF(E14="EIF",5.4)))))) -> 5.2
C15: 정책보고문 생성(시민친화) | D15: 정책보고문 시민친화 스타일 자동 생성 | E15: EO | F15: =IF(E15="","",IF(E15="EI",4,IF(E15="EO",5.2,IF(E15="EQ",3.9,IF(E15="ILF",7.5,IF(E15="EIF",5.4)))))) -> 5.2
C16: 정책보고문 생성(전문가톤) | D16: 정책보고문 전문가톤 스타일 자동 생성 | E16: EO | F16: =IF(E16="","",IF(E16="EI",4,IF(E16="EO",5.2,IF(E16="EQ",3.9,IF(E16="ILF",7.5,IF(E16="EIF",5.4)))))) -> 5.2
... C41: 가이드 위반 사례 조회 | D41: 위반 응답 탐지 목록/빈도 조회 | E41: EQ | F41: =IF(E41="","",IF(E41="EI",4,IF(E41="EO",5.2,IF(E41="EQ",3.9,IF(E41="ILF",7.5,IF(E41="EIF",5.4)))))) -> 3.9
B42: LLM 요약 | C42: 요약 정책/템플릿 저장 | D42: 문단/문서/다문서 요약 정책·템플릿 저장 | E42: ILF | F42: =IF(E42="","",IF(E42="EI",4,IF(E42="EO",5.2,IF(E42="EQ",3.9,IF(E42="ILF",7.5,IF(E42="EIF",5.4)))))) -> 7.5
C43: 요약 결과 저장소 | D43: 원문-요약문 매핑/버전 저장 | E43: ILF | F43: =IF(E43="","",IF(E43="EI",4,IF(E43="EO",5.2,IF(E43="EQ",3.9,IF(E43="ILF",7.5,IF(E43="EIF",5.4)))))) -> 7.5
C44: 문단 요약(추상적) | D44: 문단 단위 추상적 요약 처리 | E44: EO | F44: =IF(E44="","",IF(E44="EI",4,IF(E44="EO",5.2,IF(E44="EQ",3.9,IF(E44="ILF",7.5,IF(E44="EIF",5.4)))))) -> 5.2
C45: 문서 요약(추상적) | D45: 문서 단위 추상적 요약 처리 | E45: EO | F45: =IF(E45="","",IF(E45="EI",4,IF(E45="EO",5.2,IF(E45="EQ",3.9,IF(E45="ILF",7.5,IF(E45="EIF",5.4)))))) -> 5.2
C46: 다문서 요약(추상적) | D46: 다문서 단위 추상적 요약 처리 | E46: EO | F46: =IF(E46="","",IF(E46="EI",4,IF(E46="EO",5.2,IF(E46="EQ",3.9,IF(E46="ILF",7.5,IF(E46="EIF",5.4)))))) -> 5.2
C47: 타임라인 요약(추상적) | D47: 타임라인 단위 추상적 요약 처리 | E47: EO | F47: =IF(E47="","",IF(E47="EI",4,IF(E47="EO",5.2,IF(E47="EQ",3.9,IF(E47="ILF",7.5,IF(E47="EIF",5.4)))))) -> 5.2
C48: 주제별 요약(추상적) | D48: 주제별 단위 추상적 요약 처리 | E48: EO | F48: =IF(E48="","",IF(E48="EI",4,IF(E48="EO",5.2,IF(E48="EQ",3.9,IF(E48="ILF",7.5,IF(E48="EIF",5.4)))))) -> 5.2
C49: 부서별 요약(추상적) | D49: 부서별 단위 추상적 요약 처리 | E49: EO | F49: =IF(E49="","",IF(E49="EI",4,IF(E49="EO",5.2,IF(E49="EQ",3.9,IF(E49="ILF",7.5,IF(E49="EIF",5.4)))))) -> 5.2
C50: 시민용 요약(추상적) | D50: 시민용 단위 추상적 요약 처리 | E50: EO | F50: =IF(E50="","",IF(E50="EI",4,IF(E50="EO",5.2,IF(E50="EQ",3.9,IF(E50="ILF",7.5,IF(E50="EIF",5.4)))))) -> 5.2
C51: 문단 요약(추출적) | D51: 문단 단위 추출적 요약 처리 | E51: EO | F51: =IF(E51="","",IF(E51="EI",4,IF(E51="EO",5.2,IF(E51="EQ",3.9,IF(E51="ILF",7.5,IF(E51="EIF",5.4)))))) -> 5.2
C52: 문서 요약(추출적) | D52: 문서 단위 추출적 요약 처리 | E52: EO | F52: =IF(E52="","",IF(E52="EI",4,IF(E52="EO",5.2,IF(E52="EQ",3.9,IF(E52="ILF",7.5,IF(E52="EIF",5.4)))))) -> 5.2
C53: 다문서 요약(추출적) | D53: 다문서 단위 추출적 요약 처리 | E53: EO | F53: =IF(E53="","",IF(E53="EI",4,IF(E53="EO",5.2,IF(E53="EQ",3.9,IF(E53="ILF",7.5,IF(E53="EIF",5.4)))))) -> 5.2
C54: 타임라인 요약(추출적) | D54: 타임라인 단위 추출적 요약 처리 | E54: EO | F54: =IF(E54="","",IF(E54="EI",4,IF(E54="EO",5.2,IF(E54="EQ",3.9,IF(E54="ILF",7.5,IF(E54="EIF",5.4)))))) -> 5.2
... C62: 요약 편향/누락 진단 | D62: 편향·중요정보 누락 탐지 | E62: EQ | F62: =IF(E62="","",IF(E62="EI",4,IF(E62="EO",5.2,IF(E62="EQ",3.9,IF(E62="ILF",7.5,IF(E62="EIF",5.4)))))) -> 3.9
B63: LLM 리라이팅 | C63: 스타일 가이드 저장(기관별) | D63: 기관 표준문체/용어 규정 저장 | E63: ILF | F63: =IF(E63="","",IF(E63="EI",4,IF(E63="EO",5.2,IF(E63="EQ",3.9,IF(E63="ILF",7.5,IF(E63="EIF",5.4)))))) -> 7.5
C64: 스타일 가이드 저장(부서별) | D64: 부서별 특화 규칙 저장 | E64: ILF | F64: =IF(E64="","",IF(E64="EI",4,IF(E64="EO",5.2,IF(E64="EQ",3.9,IF(E64="ILF",7.5,IF(E64="EIF",5.4)))))) -> 7.5
C65: 용어/동의어 사전 저장 | D65: 표준용어/금칙어/동의어 관리 | E65: ILF | F65: =IF(E65="","",IF(E65="EI",4,IF(E65="EO",5.2,IF(E65="EQ",3.9,IF(E65="ILF",7.5,IF(E65="EIF",5.4)))))) -> 7.5
C66: 문체 변경 | D66: 경어/간결체/설명체 등 문체 전환 | E66: EO | F66: =IF(E66="","",IF(E66="EI",4,IF(E66="EO",5.2,IF(E66="EQ",3.9,IF(E66="ILF",7.5,IF(E66="EIF",5.4)))))) -> 5.2
C67: 용어 정규화 | D67: 표준 용어로 자동 치환 | E67: EO | F67: =IF(E67="","",IF(E67="EI",4,IF(E67="EO",5.2,IF(E67="EQ",3.9,IF(E67="ILF",7.5,IF(E67="EIF",5.4)))))) -> 5.2
C68: 다국어 번역 보정 | D68: 번역 후 어색한 표현 보정 | E68: EO | F68: =IF(E68="","",IF(E68="EI",4,IF(E68="EO",5.2,IF(E68="EQ",3.9,IF(E68="ILF",7.5,IF(E68="EIF",5.4)))))) -> 5.2
C69: 가독성 향상 | D69: 문장 길이/구조 최적화 | E69: EO | F69: =IF(E69="","",IF(E69="EI",4,IF(E69="EO",5.2,IF(E69="EQ",3.9,IF(E69="ILF",7.5,IF(E69="EIF",5.4)))))) -> 5.2
C70: 독해등급 조정 | D70: 읽기 수준(예: B2/C1) 맞춤 | E70: EO | F70: =IF(E70="","",IF(E70="EI",4,IF(E70="EO",5.2,IF(E70="EQ",3.9,IF(E70="ILF",7.5,IF(E70="EIF",5.4)))))) -> 5.2
C71: 포맷 적합화 | D71: 기관 양식/목차 규격 맞춤 | E71: EO | F71: =IF(E71="","",IF(E71="EI",4,IF(E71="EO",5.2,IF(E71="EQ",3.9,IF(E71="ILF",7.5,IF(E71="EIF",5.4)))))) -> 5.2
...

Sheet 05.AI Assistant 기능 개발 용역
A1: AI Assistant 기능 개발 용역
K2: (소프트웨어사업 대가산정 가이드, 24.05.13. (FP방식-간이법), KOSA)
A4: ○ 개발원가 산정 | J4: (단위 : 원)
A5: 총기능점수 | C5: 기능점수당 단가 | E5: 보정계수 | J5: 개발원가 | K5: 비고
E6: 규모 | F6: 연계복잡성 | G6: 성능 | H6: 다중사이트 | I6: 보안성
A7: =I31 -> 134.7 | C7: 605784 | E7: =J22 -> 1.28 | F7: =J23 -> 1.06 | G7: =J24 -> 1 | H7: =J25 -> 1 | I7: =J26 -> 1 | J7: =PRODUCT(A7:I7) -> 1.1071367e+08
A8: 합계(보정 후 개발원가) | J8: =SUM(J7:K7) -> 1.1071367e+08
A9: 기업이윤 | I9: 0.195 | J9: =J8*I9 -> 21589165
A10: 직접경비 | J10: -2666000
A11: 소프트웨어 개발비(부가세 별도) | J11: =J8+J9+J10 -> 1.2963683e+08
A12: 소프트웨어 개발비(부가세 포함, 10만원 이하 절사) | J12: =ROUNDDOWN(J11*1.1, -5) -> 142600000
A14: ○ 직접경비 | J14: (단위 : 원)
A15: 구분 | C15: 산출내역 | J15: 금액
A18: 합 계 | J18: =SUM(J16:K17) -> 0
A20: ○ 보정계수 산정
A21: 보정계수 구분 | C21: 복잡도 및 난이도 수준 | J21: 보정계수
A22: SW규모 | C22: ="= 0.4057 x (log e("&A7&") - 7.1978)^2 + 0.8878 (단, 500FP 미만 1.28, 3,000FP 초과 1.153 적용)" -> = 0.4057 x (log e(134.7) - 7.1978)^2 + 0.8878 (단, 500FP 미만 1.28, 3,000FP 초과 1.153 적용) | J22: =IF(A7<500,1.28,IF(A7>3000,1.153,0.4057*(LN(A7)-7.1978)^2+0.8878)) -> 1.28
A23: 연계복잡성 | C23: 4. 6~10개의 타 기관 연계 | J23: =VLOOKUP(C23,M23:N27,2,1) -> 1.06 | M23: 1. 타 기관 연계 없음 | N23: 0.88
A24: 성능 요구수준 | C24: 3. 응답시간이나 처리율이 피크타임(peak time)에 중요하며, 처리 시한이 명시되어 있다. | J24: =VLOOKUP(C24,M28:N32,2,1) -> 1 | M24: 2. 1~2개의 타 기관 연계 | N24: 0.94
A25: 다중사이트 운영성 | C25: 2. 다중사이트 운영성에 대한 요구사항이 있으며, 동일 하드웨어 및 소프트웨어 환경에서 운영되도록 설계된다. | J25: =VLOOKUP(C25,M33:N37,2,1) -> 1 | M25: 3. 3~5개의 타 기관 연계 | N25: 1
A26: 보안성 요구수준 | C26: 2. 위의 4가지 항목 중 2가지 요구사항이 포함되어 있다. | J26: =VLOOKUP(C26,M38:N42,2,1) -> 1 | M26: 4. 6~10개의 타 기관 연계 | N26: 1.06
M27: 5. 10개 초과의 타 기관 연계 | N27: 1.12
A28: ○ FP 집계 | M28: 1. 응답성능에 대한 특별한 요구사항이 없다. | N28: 0.91
A29: 구분 | D29: ILF | E29: EIF | F29: EI | G29: EO | H29: EQ | I29: 계 | M29: 2. 응답성능에 대한 요구사항이 있으나 특별한 조치가 필요하지는 않다. | N29: 0.95
A30: 기능수 | D30: =COUNTIF('05.AI Assistant 기능 FP산정'!E4:E82,"ILF") -> 4 | E30: =COUNTIF('05.AI Assistant 기능 FP산정'!E4:E82,"EIF") -> 0 | F30: =COUNTIF('05.AI Assistant 기능 FP산정'!E4:E82,"EI") -> 7 | G30: =COUNTIF('05.AI Assistant 기능 FP산정'!E4:E82,"EO") -> 11 | H30: =COUNTIF('05.AI Assistant 기능 FP산정'!E4:E82,"EQ") -> 5 | I30: =SUM(D30:H30) -> 27 | M30: 3. 응답시간이나 처리율이 피크타임(peak time)에 중요하며, 처리 시한이 명시되어 있다. | N30: 1
A31: 기능점수 | D31: =SUMIF('05.AI Assistant 기능 FP산정'!E4:E82,"ILF",'05.AI Assistant 기능 FP산정'!$F4:$F82) -> 30 | E31: =SUMIF('05.AI Assistant 기능 FP산정'!E4:E82,"EIF",'05.AI Assistant 기능 FP산정'!$F4:$F82) -> 0 | F31: =SUMIF('05.AI Assistant 기능 FP산정'!E4:E82,"EI",'05.AI Assistant 기능 FP산정'!$F4:$F82) -> 28 | G31: =SUMIF('05.AI Assistant 기능 FP산정'!E4:E82,"EO",'05.AI Assistant 기능 FP산정'!$F4:$F82) -> 57.2 | H31: =SUMIF('05.AI Assistant 기능 FP산정'!E4:E82,"EQ",'05.AI Assistant 기능 FP산정'!$F4:$F82) -> 19.5 | I31: =SUM(D31:H31) -> 134.7 | M31: 4. 응답시간이나 처리율이 모든 업무시간에 중요하며, 처리 시한이 명시되어 있다. | N31: 1.05
A32: 비중 | D32: =IF($I$31>0,D31/$I$31,"-") -> 0.22271715 | E32: =IF($I$31>0,E31/$I$31,"-") -> 0 | F32: =IF($I$31>0,F31/$I$31,"-") -> 0.20786934 | G32: =IF($I$31>0,G31/$I$31,"-") -> 0.42464736 | H32: =IF($I$31>0,H31/$I$31,"-") -> 0.14476615 | I32: =SUM(D32:H32) -> 1 | M32: 5. 응답성능 요구수준이 엄격하여, 설계, 개발 또는 구현 단계에서 성능 분석도구 사용이 필요하다. | N32: 1.09
M33: 1. 다중사이트 운영성에 대한 요구사항이 없다. | N33: 0.94
M34: 2. 다중사이트 운영성에 대한 요구사항이 있으며, 동일 하드웨어 및 소프트웨어 환경에서 운영되도록 설계된다. | N34: 1
M35: 3. 다중사이트 운영성에 대한 요구사항이 있으며, 유사 하드웨어 및 소프트웨어 환경에서 운영되도록 설계된다. | N35: 1.06
M36: 4. 다중사이트 운영성에 대한 요구사항이 있으며, 이질적인 하드웨어 및 소프트웨어 환경에서 운영되도록 설계된다. | N36: 1.13
M37: 5. 항목 4에 더하여 일반적 산출물 이외에 다중사이트에서 원활한 운영을 보장하기 위한 운영 절차의 문서화와 사전 모의훈련이 요구된다. | N37: 1.19
M38: 1. 암호화, 웹취약점 점검, 시큐어코딩, 개인정보보호 중 1가지 요구사항이 포함되어 있다. | N38: 0.97
M39: 2. 위의 4가지 항목 중 2가지 요구사항이 포함되어 있다. | N39: 1
M40: 3. 위의 4가지 항목 중 3가지 요구사항이 포함되어 있다. | N40: 1.03
M41: 4. 위의 4가지 항목이 모두 포함되어 있다. | N41: 1.06
M42: 5. 항목 4)에 더하여 추가적인 요구사항이 있다. | N42: 1.08
A44: FP산정
A45: FP산정

Sheet 05.AI Assistant 기능 FP산정
A1: AI Assistant 기능점수
A2: 기능명 | E2: 데이터 및 트랜잭션 기능 | F2: FP 산출 | G2: 비고
A3: ①어플리 케이션명 | B3: ②세부 업무명 | C3: ③단위프로세스명 | D3: 단위프로세스 설명 | E3: ④FP유형 | F3: ⑤가중치
A4: 공영주차장 스마트 안전 AI 분석 솔루션 | B4: 다국어 대응 | C4: 다국어 FAQ 저장소 | D4: FAQ 원문/번역 매핑 저장 | E4: ILF | F4: =IF(E4="","",IF(E4="EI",4,IF(E4="EO",5.2,IF(E4="EQ",3.9,IF(E4="ILF",7.5,IF(E4="EIF",5.4)))))) -> 7.5
B5: 다국어 대응 | C5: 질의 번역 처리 | D5: 한국어↔영/중 질의 번역 | E5: EI | F5: =IF(E5="","",IF(E5="EI",4,IF(E5="EO",5.2,IF(E5="EQ",3.9,IF(E5="ILF",7.5,IF(E5="EIF",5.4)))))) -> 4
B6: 다국어 대응 | C6: 응답 번역 처리 | D6: 응답 다국어 변환 | E6: EO | F6: =IF(E6="","",IF(E6="EI",4,IF(E6="EO",5.2,IF(E6="EQ",3.9,IF(E6="ILF",7.5,IF(E6="EIF",5.4)))))) -> 5.2
B7: 다국어 대응 | C7: 번역 품질 검증 조회 | D7: BLEU/TER 기반 번역 검증 | E7: EQ | F7: =IF(E7="","",IF(E7="EI",4,IF(E7="EO",5.2,IF(E7="EQ",3.9,IF(E7="ILF",7.5,IF(E7="EIF",5.4)))))) -> 3.9
B8: 지식 관리 | C8: 정책문서 인덱스 저장 | D8: 정책·조례·규정 벡터 인덱스 저장 | E8: ILF | F8: =IF(E8="","",IF(E8="EI",4,IF(E8="EO",5.2,IF(E8="EQ",3.9,IF(E8="ILF",7.5,IF(E8="EIF",5.4)))))) -> 7.5
B9: 지식 관리 | C9: RAG 검색 처리 | D9: 질의→문서 검색 결과 반환 | E9: EO | F9: =IF(E9="","",IF(E9="EI",4,IF(E9="EO",5.2,IF(E9="EQ",3.9,IF(E9="ILF",7.5,IF(E9="EIF",5.4)))))) -> 5.2
B10: 지식 관리 | C10: 근거 문서 하이라이팅 출력 | D10: 원문 근거 구절/하이라이트 표시 | E10: EO | F10: =IF(E10="","",IF(E10="EI",4,IF(E10="EO",5.2,IF(E10="EQ",3.9,IF(E10="ILF",7.5,IF(E10="EIF",5.4)))))) -> 5.2
B11: 지식 관리 | C11: 정책 메모 자동 작성 | D11: 정책 보고용 요약/메모 생성 | E11: EO | F11: =IF(E11="","",IF(E11="EI",4,IF(E11="EO",5.2,IF(E11="EQ",3.9,IF(E11="ILF",7.5,IF(E11="EIF",5.4)))))) -> 5.2
B12: 지식 관리 | C12: 검색 정확도 검증 조회 | D12: 검색 성능 통계/리포트 조회 | E12: EQ | F12: =IF(E12="","",IF(E12="EI",4,IF(E12="EO",5.2,IF(E12="EQ",3.9,IF(E12="ILF",7.5,IF(E12="EIF",5.4)))))) -> 3.9
B13: 대화 관리 | C13: 세션/컨텍스트 저장 | D13: 대화 이력·컨텍스트 저장 | E13: ILF | F13: =IF(E13="","",IF(E13="EI",4,IF(E13="EO",5.2,IF(E13="EQ",3.9,IF(E13="ILF",7.5,IF(E13="EIF",5.4)))))) -> 7.5
B14: 대화 관리 | C14: 반복 민원 응답 이력 조회 | D14: 과거 응답 매칭 조회 | E14: EQ | F14: =IF(E14="","",IF(E14="EI",4,IF(E14="EO",5.2,IF(E14="EQ",3.9,IF(E14="ILF",7.5,IF(E14="EIF",5.4)))))) -> 3.9
B15: 대화 관리 | C15: 관리자 승인 워크플로우 처리 | D15: 응답 생성→관리자 승인 | E15: EI | F15: =IF(E15="","",IF(E15="EI",4,IF(E15="EO",5.2,IF(E15="EQ",3.9,IF(E15="ILF",7.5,IF(E15="EIF",5.4)))))) -> 4
B16: 응답 고도화 | C16: 추천 응답(민원) 생성 | D16: 민원 대응용 응답 자동생성 | E16: EO | F16: =IF(E16="","",IF(E16="EI",4,IF(E16="EO",5.2,IF(E16="EQ",3.9,IF(E16="ILF",7.5,IF(E16="EIF",5.4)))))) -> 5.2
... B30: 연계 서비스 | C30: 외부 지자체 데이터 연계 | D30: 전북도청 컨설팅 데이터 연계 | E30: EI | F30: =IF(E30="","",IF(E30="EI",4,IF(E30="EO",5.2,IF(E30="EQ",3.9,IF(E30="ILF",7.5,IF(E30="EIF",5.4)))))) -> 4
F31: =IF(E31="","",IF(E31="EI",4,IF(E31="EO",5.2,IF(E31="EQ",3.9,IF(E31="ILF",7.5,IF(E31="EIF",5.4))))))
A32: * 기능점수 산정 참고 | F32: =SUM(F4:F30) -> 134.7
A33: * FP 유형 = EI (Exteranl Input : 외부입력) EO (External Output : 외부출력) EQ (External Inquiries : 외부조회)
A34: ILF (Internal Logical Files : 내부논리파일) EIF(Externa Interface Files : 외부연계 파일)
A36: * 용어설명
A37: *ILF : 사용자 관점에서 식별 가능한, 논리적으로 연관된 하나의 데이터그룹 또는 제어정보로서 측정대상 애플리케이션 내부에서 유지되는 파일
A38: *EIF : 사용자 관점에서 식별 가능한, 사용자가 식별할 수 있는 논리적으로 연관된 하나의 데이터그룹 또는 제어정보로서
A39: 측정대상 애플리케이션 내부에서는 오직 참조만 되고 다른 애플리케이션에서 유지되는 파일
A40: *EI : 애플리케이션 경계 밖에서 들어오는 데이터나 제어정보를 처리하는 단위 프로세스로서, 하나 이상의 논리파일을 변경하거나 시스템 동작을 변경함
A41: *EO : 데이터나 제어정보 애플리케이션 경계 밖의 사용자에게 보여주는단위프로세스로서, 데이터나 제어정보에 처리로직이 적용됨.
A42: 처리로직은 하나 이상의 수학적 계산, 공식 또는 파생 데이터를 포함하거나, 하나 이상의 내부논리파일(ILF)의 유지관리 작업이 발생하거나,
A43: 시스템의 동작 변경이 수반됨
A44: *EQ : 데이터나 제어정보를 애플리케이션 경계 밖으로 보여주는 단위프로세스로서, 데이터나 제어정보를 단순히 사용자에게 제공함.
A45: 외부조회는 수학적 계산이나 공식을 사용하지 않으며, 파생 데이터도 생성하지 않음.
A46: 처리 과정에서 내부논리파일(ILF)의 유지관리작업이 발생하지 않으며 시스템의 동작도 변경하지 않음
G47: =IF(F47="","",IF(F47="EI",4,IF(F47="EO",5.2,IF(F47="EQ",3.9,IF(F47="ILF",7.5,IF(F47="EIF",5.4))))))

Sheet 06.대시보드 및 시각화 개발 용역
A1: 대시보드 및 시각화 개발 용역
K2: (소프트웨어사업 대가산정 가이드, 24.05.13. (FP방식-간이법), KOSA)
A4: ○ 개발원가 산정 | J4: (단위 : 원)
A5: 총기능점수 | C5: 기능점수당 단가 | E5: 보정계수 | J5: 개발원가 | K5: 비고
E6: 규모 | F6: 연계복잡성 | G6: 성능 | H6: 다중사이트 | I6: 보안성
A7: =I31 -> 377.9 | C7: 605784 | E7: =J22 -> 1.28 | F7: =J23 -> 1.06 | G7: =J24 -> 1 | H7: =J25 -> 1 | I7: =J26 -> 1 | J7: =PRODUCT(A7:I7) -> 3.1060649e+08
A8: 합계(보정 후 개발원가) | J8: =SUM(J7:K7) -> 3.1060649e+08
A9: 기업이윤 | I9: 0.195 | J9: =J8*I9 -> 60568265
A10: 직접경비 | J10: -9083000
A11: 소프트웨어 개발비(부가세 별도) | J11: =J8+J9+J10 -> 3.6209176e+08
A12: 소프트웨어 개발비(부가세 포함, 10만원 이하 절사) | J12: =ROUNDDOWN(J11*1.1, -5) -> 398300000
A14: ○ 직접경비 | J14: (단위 : 원)
A15: 구분 | C15: 산출내역 | J15: 금액
A18: 합 계 | J18: =SUM(J16:K17) -> 0
A20: ○ 보정계수 산정
A21: 보정계수 구분 | C21: 복잡도 및 난이도 수준 | J21: 보정계수
A22: SW규모 | C22: ="= 0.4057 x (log e("&A7&") - 7.1978)^2 + 0.8878 (단, 500FP 미만 1.28, 3,000FP 초과 1.153 적용)" -> = 0.4057 x (log e(377.9) - 7.1978)^2 + 0.8878 (단, 500FP 미만 1.28, 3,000FP 초과 1.153 적용) | J22: =IF(A7<500,1.28,IF(A7>3000,1.153,0.4057*(LN(A7)-7.1978)^2+0.8878)) -> 1.28
A23: 연계복잡성 | C23: 4. 6~10개의 타 기관 연계 | J23: =VLOOKUP(C23,M23:N27,2,1) -> 1.06 | M23: 1. 타 기관 연계 없음 | N23: 0.88
A24: 성능 요구수준 | C24: 3. 응답시간이나 처리율이 피크타임(peak time)에 중요하며, 처리 시한이 명시되어 있다. | J24: =VLOOKUP(C24,M28:N32,2,1) -> 1 | M24: 2. 1~2개의 타 기관 연계 | N24: 0.94
A25: 다중사이트 운영성 | C25: 2. 다중사이트 운영성에 대한 요구사항이 있으며, 동일 하드웨어 및 소프트웨어 환경에서 운영되도록 설계된다. | J25: =VLOOKUP(C25,M33:N37,2,1) -> 1 | M25: 3. 3~5개의 타 기관 연계 | N25: 1
A26: 보안성 요구수준 | C26: 2. 위의 4가지 항목 중 2가지 요구사항이 포함되어 있다. | J26: =VLOOKUP(C26,M38:N42,2,1) -> 1 | M26: 4. 6~10개의 타 기관 연계 | N26: 1.06
M27: 5. 10개 초과의 타 기관 연계 | N27: 1.12
A28: ○ FP 집계 | M28: 1. 응답성능에 대한 특별한 요구사항이 없다. | N28: 0.91
A29: 구분 | D29: ILF | E29: EIF | F29: EI | G29: EO | H29: EQ | I29: 계 | M29: 2. 응답성능에 대한 요구사항이 있으나 특별한 조치가 필요하지는 않다. | N29: 0.95
A30: 기능수 | D30: =COUNTIF('06.대시보드 및 시각화 FP산정'!E4:E112,"ILF") -> 37 | E30: =COUNTIF('06.대시보드 및 시각화 FP산정'!E4:E112,"EIF") -> 0 | F30: =COUNTIF('06.대시보드 및 시각화 FP산정'!E4:E112,"EI") -> 3 | G30: =COUNTIF('06.대시보드 및 시각화 FP산정'!E4:E112,"EO") -> 17 | H30: =COUNTIF('06.대시보드 및 시각화 FP산정'!E4:E112,"EQ") -> 0 | I30: =SUM(D30:H30) -> 57 | M30: 3. 응답시간이나 처리율이 피크타임(peak time)에 중요하며, 처리 시한이 명시되어 있다. | N30: 1
A31: 기능점수 | D31: =SUMIF('06.대시보드 및 시각화 FP산정'!E4:E112,"ILF",'06.대시보드 및 시각화 FP산정'!$F4:$F112) -> 277.5 | E31: =SUMIF('06.대시보드 및 시각화 FP산정'!E4:E112,"EIF",'06.대시보드 및 시각화 FP산정'!$F4:$F112) -> 0 | F31: =SUMIF('06.대시보드 및 시각화 FP산정'!E4:E112,"EI",'06.대시보드 및 시각화 FP산정'!$F4:$F112) -> 12 | G31: =SUMIF('06.대시보드 및 시각화 FP산정'!E4:E112,"EO",'06.대시보드 및 시각화 FP산정'!$F4:$F112) -> 88.4 | H31: =SUMIF('06.대시보드 및 시각화 FP산정'!E4:E112,"EQ",'06.대시보드 및 시각화 FP산정'!$F4:$F112) -> 0 | I31: =SUM(D31:H31) -> 377.9 | M31: 4. 응답시간이나 처리율이 모든 업무시간에 중요하며, 처리 시한이 명시되어 있다. | N31: 1.05
A32: 비중 | D32: =IF($I$31>0,D31/$I$31,"-") -> 0.73432125 | E32: =IF($I$31>0,E31/$I$31,"-") -> 0 | F32: =IF($I$31>0,F31/$I$31,"-") -> 0.031754432 | G32: =IF($I$31>0,G31/$I$31,"-") -> 0.23392432 | H32: =IF($I$31>0,H31/$I$31,"-") -> 0 | I32: =SUM(D32:H32) -> 1 | M32: 5. 응답성능 요구수준이 엄격하여, 설계, 개발 또는 구현 단계에서 성능 분석도구 사용이 필요하다. | N32: 1.09
M33: 1. 다중사이트 운영성에 대한 요구사항이 없다. | N33: 0.94
M34: 2. 다중사이트 운영성에 대한 요구사항이 있으며, 동일 하드웨어 및 소프트웨어 환경에서 운영되도록 설계된다. | N34: 1
M35: 3. 다중사이트 운영성에 대한 요구사항이 있으며, 유사 하드웨어 및 소프트웨어 환경에서 운영되도록 설계된다. | N35: 1.06
M36: 4. 다중사이트 운영성에 대한 요구사항이 있으며, 이질적인 하드웨어 및 소프트웨어 환경에서 운영되도록 설계된다. | N36: 1.13
M37: 5. 항목 4에 더하여 일반적 산출물 이외에 다중사이트에서 원활한 운영을 보장하기 위한 운영 절차의 문서화와 사전 모의훈련이 요구된다. | N37: 1.19
M38: 1. 암호화, 웹취약점 점검, 시큐어코딩, 개인정보보호 중 1가지 요구사항이 포함되어 있다. | N38: 0.97
M39: 2. 위의 4가지 항목 중 2가지 요구사항이 포함되어 있다. | N39: 1
M40: 3. 위의 4가지 항목 중 3가지 요구사항이 포함되어 있다. | N40: 1.03
M41: 4. 위의 4가지 항목이 모두 포함되어 있다. | N41: 1.06
M42: 5. 항목 4)에 더하여 추가적인 요구사항이 있다. | N42: 1.08
A44: FP산정
A45: FP산정

Sheet 06.대시보드 및 시각화 FP산정
A1: 대시보드 및 시각화 기능점수
A2: 기능명 | E2: 데이터 및 트랜잭션 기능 | F2: FP 산출 | G2: 비고
A3: ①어플리 케이션명 | B3: ②세부 업무명 | C3: ③단위프로세스명 | D3: 단위프로세스 설명 | E3: ④FP유형 | F3: ⑤가중치
A4: 공영주차장 스마트 안전 AI 분석 솔루션 | B4: 민원 분석 대응 서비스 데이터 | C4: 제주시 민원 정보 DB | D4: AI 솔루션이 수집-정제-가공한 민원정보 | E4: ILF | F4: =IF(E4="","",IF(E4="EI",4,IF(E4="EO",5.2,IF(E4="EQ",3.9,IF(E4="ILF",7.5,IF(E4="EIF",5.4)))))) -> 7.5
C5: 서귀포시 민원 정보 DB | D5: AI 솔루션이 수집-정제-가공한 민원정보 | E5: ILF | F5: =IF(E5="","",IF(E5="EI",4,IF(E5="EO",5.2,IF(E5="EQ",3.9,IF(E5="ILF",7.5,IF(E5="EIF",5.4)))))) -> 7.5
C6: 만덕콜센터 민원 정보 DB | D6: AI 솔루션이 수집-정제-가공한 민원정보 | E6: ILF | F6: =IF(E6="","",IF(E6="EI",4,IF(E6="EO",5.2,IF(E6="EQ",3.9,IF(E6="ILF",7.5,IF(E6="EIF",5.4)))))) -> 7.5
C7: 제주시 민원 정보 RAW-Dtata | D7: 가공전 민원 원본 정보 | E7: ILF | F7: =IF(E7="","",IF(E7="EI",4,IF(E7="EO",5.2,IF(E7="EQ",3.9,IF(E7="ILF",7.5,IF(E7="EIF",5.4)))))) -> 7.5
C8: 서귀포시 민원정보 RAW-Data | D8: 가공전 민원 원본 정보 | E8: ILF | F8: =IF(E8="","",IF(E8="EI",4,IF(E8="EO",5.2,IF(E8="EQ",3.9,IF(E8="ILF",7.5,IF(E8="EIF",5.4)))))) -> 7.5
C9: 만덕콜 센터 민원 정보 RAW-Data | D9: 가공전 민원 원본 정보 | E9: ILF | F9: =IF(E9="","",IF(E9="EI",4,IF(E9="EO",5.2,IF(E9="EQ",3.9,IF(E9="ILF",7.5,IF(E9="EIF",5.4)))))) -> 7.5
C10: 국민 신문고 민원 정보 DB | D10: AI 솔루션이 수집-정제-가공한 민원정보 | E10: ILF | F10: =IF(E10="","",IF(E10="EI",4,IF(E10="EO",5.2,IF(E10="EQ",3.9,IF(E10="ILF",7.5,IF(E10="EIF",5.4)))))) -> 7.5
C11: 국민 신문고 민원 정보 RAW-Data | D11: 가공전 민원 원본 정보 | E11: ILF | F11: =IF(E11="","",IF(E11="EI",4,IF(E11="EO",5.2,IF(E11="EQ",3.9,IF(E11="ILF",7.5,IF(E11="EIF",5.4)))))) -> 7.5
C12: 기상청 기상예보정보 (단기예보구역) | D12: 단기예보 시·공간 세분화 발표 예보 정보 | E12: ILF | F12: =IF(E12="","",IF(E12="EI",4,IF(E12="EO",5.2,IF(E12="EQ",3.9,IF(E12="ILF",7.5,IF(E12="EIF",5.4)))))) -> 7.5
C13: 기상청 기상예보정보 (단기개황) | D13: 단기개황 시·공간 세분화 발표 예보 정보 | E13: ILF | F13: =IF(E13="","",IF(E13="EI",4,IF(E13="EO",5.2,IF(E13="EQ",3.9,IF(E13="ILF",7.5,IF(E13="EIF",5.4)))))) -> 7.5
C14: 기상청 기상예보정보 (단기육상) | D14: 단기육상 기상 시·공간 세분화 발표 예보 정보 | E14: ILF | F14: =IF(E14="","",IF(E14="EI",4,IF(E14="EO",5.2,IF(E14="EQ",3.9,IF(E14="ILF",7.5,IF(E14="EIF",5.4)))))) -> 7.5
C15: 기상청 기상예보정보 (단기해상) | D15: 단기해상 기상 시·공간 세분화 발표 예보 정보 | E15: ILF | F15: =IF(E15="","",IF(E15="EI",4,IF(E15="EO",5.2,IF(E15="EQ",3.9,IF(E15="ILF",7.5,IF(E15="EIF",5.4)))))) -> 7.5
C16: 기상청 기상예보정보 (단기동네) | D16: 단기 동네 예보 | E16: ILF | F16: =IF(E16="","",IF(E16="EI",4,IF(E16="EO",5.2,IF(E16="EQ",3.9,IF(E16="ILF",7.5,IF(E16="EIF",5.4)))))) -> 7.5
... C60: 히트맵 단위 이벤트 발생 빈도 표출 | D60: 히트맵 단위 이벤트 발생 빈도 표출 | E60: EO | F60: =IF(E60="","",IF(E60="EI",4,IF(E60="EO",5.2,IF(E60="EQ",3.9,IF(E60="ILF",7.5,IF(E60="EIF",5.4)))))) -> 5.2
F61: =IF(E61="","",IF(E61="EI",4,IF(E61="EO",5.2,IF(E61="EQ",3.9,IF(E61="ILF",7.5,IF(E61="EIF",5.4))))))
A62: * 기능점수 산정 참고 | F62: =SUM(F4:F60) -> 377.9
A63: * FP 유형 = EI (Exteranl Input : 외부입력) EO (External Output : 외부출력) EQ (External Inquiries : 외부조회)
A64: ILF (Internal Logical Files : 내부논리파일) EIF(Externa Interface Files : 외부연계 파일)
A66: * 용어설명
A67: *ILF : 사용자 관점에서 식별 가능한, 논리적으로 연관된 하나의 데이터그룹 또는 제어정보로서 측정대상 애플리케이션 내부에서 유지되는 파일
A68: *EIF : 사용자 관점에서 식별 가능한, 사용자가 식별할 수 있는 논리적으로 연관된 하나의 데이터그룹 또는 제어정보로서
A69: 측정대상 애플리케이션 내부에서는 오직 참조만 되고 다른 애플리케이션에서 유지되는 파일
A70: *EI : 애플리케이션 경계 밖에서 들어오는 데이터나 제어정보를 처리하는 단위 프로세스로서, 하나 이상의 논리파일을 변경하거나 시스템 동작을 변경함
A71: *EO : 데이터나 제어정보 애플리케이션 경계 밖의 사용자에게 보여주는단위프로세스로서, 데이터나 제어정보에 처리로직이 적용됨.
A72: 처리로직은 하나 이상의 수학적 계산, 공식 또는 파생 데이터를 포함하거나, 하나 이상의 내부논리파일(ILF)의 유지관리 작업이 발생하거나,
A73: 시스템의 동작 변경이 수반됨
A74: *EQ : 데이터나 제어정보를 애플리케이션 경계 밖으로 보여주는 단위프로세스로서, 데이터나 제어정보를 단순히 사용자에게 제공함.
A75: 외부조회는 수학적 계산이나 공식을 사용하지 않으며, 파생 데이터도 생성하지 않음.
A76: 처리 과정에서 내부논리파일(ILF)의 유지관리작업이 발생하지 않으며 시스템의 동작도 변경하지 않음
G77: =IF(F77="","",IF(F77="EI",4,IF(F77="EO",5.2,IF(F77="EQ",3.9,IF(F77="ILF",7.5,IF(F77="EIF",5.4))))))

Sheet 07. 데이터 표준화 모델
A1: "데이터 표준화" 산출내역서- 투입공수에 의한 방식
H2: (소프트웨어사업 대가산정 가이드, 2025. KOSA)
A4: ○ 투입공수 방식 SW운영비 산정 | H4: (단위 : 원)
A5: 업무 구분 | C5: 직무 | D5: 투입구분 | E5: ⓐ평균임금 (Month) | F5: ⓑ투입기간 (Month) | G5: ⓒ투입률 (업무 비중) | H5: 직접인건비 (ⓐxⓑxⓒ)
A6: 1 | B6: 데이터 표준화 전략 수립 및 컨설팅 | C6: ② IT컨설턴트 | D6: 평균 | E6: =IFERROR(INDEX($B$28:$E$45,MATCH($C6,$B$28:$B$45,0),MATCH($D6,$B$28:$E$28,0)),"") -> 9706020 | F6: 6 | G6: 0.5 | H6: =IFERROR(E6*F6*G6,"") -> 29118060
A7: 2 | B7: 표준 데이터모델 정의 및 메타데이터 분석 | C7: ④ 데이터분석가 | D7: 평균 | E7: =IFERROR(INDEX($B$28:$E$45,MATCH($C7,$B$28:$B$45,0),MATCH($D7,$B$28:$E$28,0)),"") -> 7751183 | F7: 6 | G7: 0.3 | H7: =IFERROR(E7*F7*G7,"") -> 13952129
A8: 3 | B8: 표준 준수 검증 및 품질 관리 | C8: ⑭ IT품질관리자 | D8: 평균 | E8: =IFERROR(INDEX($B$28:$E$45,MATCH($C8,$B$28:$B$45,0),MATCH($D8,$B$28:$E$28,0)),"") -> 9692094 | F8: 6 | G8: 0.3 | H8: =IFERROR(E8*F8*G8,"") -> 17445769
A9: 4 | B9: 표준모델 적용 시험 및 호환성 검증 | C9: ⑮ IT테스터 | D9: 평균 | E9: =IFERROR(INDEX($B$28:$E$45,MATCH($C9,$B$28:$B$45,0),MATCH($D9,$B$28:$E$28,0)),"") -> 3570557 | F9: 6 | G9: 0.3 | H9: =IFERROR(E9*F9*G9,"") -> 6427002.6
A10: 5 | B10: 업무 프로세스 분석 및 표준요건 도출 | C10: ③ 업무분석가 | D10: 평균 | E10: =IFERROR(INDEX($B$28:$E$45,MATCH($C10,$B$28:$B$45,0),MATCH($D10,$B$28:$E$28,0)),"") -> 8997359 | F10: 6 | G10: 0.5 | H10: =IFERROR(E10*F10*G10,"") -> 26992077
A11: 총 투입공수 | C11: 투입기간 * 투입률 | F11: =SUMPRODUCT(F6:F10,G6:G10) -> 11.4
A12: 직접인건비 합계 | C12: ∑(직무별 투입공수 x 평균임금) | F12: =SUM(H6:H10) -> 93935038
A13: 제경비 | B13: 0 | C13: 직접인건비의 110~120% | F13: =F12*B13 -> 0
A14: 기술료 | B14: 0 | C14: (직접인건비 + 제경비)의 15~40% | F14: =(F12+F13)*B14 -> 0
A15: 직접경비 | C15: 해당사항없음
A16: 소프트웨어 운영비(부가세 별도) | C16: 직접인건비 + 제경비 + 기술료 + 직접경비 | F16: =SUM(F12:H15) -> 93935038
A17: 절사금액 | C17: 조정(단가조정) | F17: 2727273
A18: 부가가치세 | C18: (소프트웨어 운영비-절사금액)*10% | F18: =(F16-F17)*10% -> 9120776.5
A19: 소프트웨어 운영비(부가세 포함) | F19: =(F16-F17)+F18 -> 1.0032854e+08
A20: *상기견적은 제경비율 110%, 기술료 15%를 적용함
B28: 구 분 | C28: 평균 | D28: 하위 | E28: 상위
B29: ① IT기획자 | C29: 11597656 | D29: 382762 | E29: 861867
B30: ② IT컨설턴트 | C30: 9706020 | D30: 245906 | E30: 536687
B31: ③ 업무분석가 | C31: 8997359 | D31: 393290 | E31: 484501
B32: ④ 데이터분석가 | C32: 7751183 | D32: 286364 | E32: 473463
B33: ⑤ IT PM | C33: 9145473 | D33: 325796 | E33: 596003
B34: ⑥ IT아키텍트 | C34: 10147745 | D34: 352792 | E34: 576762
B35: ⑦ UI/UX기획/개발자 | C35: 6727260 | D35: 203098 | E35: 412481
B36: ⑧ UI/UX디자이너 | C36: 5176203 | D36: 166546 | E36: 407614
B37: ⑨ 응용SW개발자 | C37: 6943457 | D37: 219087 | E37: 449024
B38: ⑩ 시스템SW개발자 | C38: 6099042 | D38: 198151 | E38: 350864
B39: ⑪ 정보시스템운용자 | C39: 10154626 | D39: 283779 | E39: 783171
